Workbook

Sheet 지역별 유출률
A1: 지역별 관외 유출률 (2011~2024)
A3: 연도별 유출률과 2011~2024 평균. 행정구역 신설·통폐합으로 없는 연도는 빈칸이며 평균은 값이 존재하는 연도만 사용.
A5: 시도 | B5: 시군구 | C5: 지역명 | D5: 2011 | E5: 2012 | F5: 2013 | G5: 2014 | H5: 2015 | I5: 2016 | J5: 2017 | K5: 2018 | L5: 2019 | M5: 2020 | N5: 2021 | O5: 2022 | P5: 2023 | Q5: 2024 | R5: 2011~2024 평균 | S5: 관측연도 수
A6: 서울 | B6: 전체 | C6: 서울 | D6: =원천데이터!G6 -> 0.19331733 | E6: =원천데이터!G269 -> 0.19325337 | F6: =원천데이터!G532 -> 0.19393007 | G6: =원천데이터!G799 -> 0.19680529 | H6: =원천데이터!G1067 -> 0.1964465 | I6: =원천데이터!G1335 -> 0.1984181 | J6: =원천데이터!G1601 -> 0.19922236 | K6: =원천데이터!G1867 -> 0.19950336 | L6: =원천데이터!G2133 -> 0.20066118 | M6: =원천데이터!G2399 -> 0.19028605 | N6: =원천데이터!G2665 -> 0.19502784 | O6: =원천데이터!G2931 -> 0.21425469 | P6: =원천데이터!G3197 -> 0.21190936 | Q6: =원천데이터!G3463 -> 0.21071362 | R6: =IFERROR(AVERAGE(D6:Q6),"") -> 0.19955351 | S6: =COUNT(D6:Q6) -> 14
A7: 서울 | B7: 강남구 | C7: 서울 강남구 | D7: =원천데이터!G7 -> 0.450728 | E7: =원천데이터!G270 -> 0.44954505 | F7: =원천데이터!G533 -> 0.44966825 | G7: =원천데이터!G800 -> 0.45691829 | H7: =원천데이터!G1068 -> 0.45910185 | I7: =원천데이터!G1336 -> 0.45639047 | J7: =원천데이터!G1602 -> 0.45597491 | K7: =원천데이터!G1868 -> 0.45651035 | L7: =원천데이터!G2134 -> 0.4593096 | M7: =원천데이터!G2400 -> 0.45841844 | N7: =원천데이터!G2666 -> 0.46314207 | O7: =원천데이터!G2932 -> 0.45670585 | P7: =원천데이터!G3198 -> 0.46136106 | Q7: =원천데이터!G3464 -> 0.45870089 | R7: =IFERROR(AVERAGE(D7:Q7),"") -> 0.45660536 | S7: =COUNT(D7:Q7) -> 14
A8: 서울 | B8: 강동구 | C8: 서울 강동구 | D8: =원천데이터!G8 -> 0.4005141 | E8: =원천데이터!G271 -> 0.39483815 | F8: =원천데이터!G534 -> 0.39435887 | G8: =원천데이터!G801 -> 0.39459203 | H8: =원천데이터!G1069 -> 0.39750889 | I8: =원천데이터!G1337 -> 0.39905235 | J8: =원천데이터!G1603 -> 0.40270353 | K8: =원천데이터!G1869 -> 0.40288328 | L8: =원천데이터!G2135 -> 0.4127019 | M8: =원천데이터!G2401 -> 0.40968037 | N8: =원천데이터!G2667 -> 0.41256127 | O8: =원천데이터!G2933 -> 0.41492241 | P8: =원천데이터!G3199 -> 0.41900526 | Q8: =원천데이터!G3465 -> 0.42474237 | R8: =IFERROR(AVERAGE(D8:Q8),"") -> 0.40571891 | S8: =COUNT(D8:Q8) -> 14
A9: 서울 | B9: 강북구 | C9: 서울 강북구 | D9: =원천데이터!G9 -> 0.46984493 | E9: =원천데이터!G272 -> 0.46649495 | F9: =원천데이터!G535 -> 0.46816538 | G9: =원천데이터!G802 -> 0.46738307 | H9: =원천데이터!G1070 -> 0.46513118 | I9: =원천데이터!G1338 -> 0.46596116 | J9: =원천데이터!G1604 -> 0.46719021 | K9: =원천데이터!G1870 -> 0.46802556 | L9: =원천데이터!G2136 -> 0.46940949 | M9: =원천데이터!G2402 -> 0.46652199 | N9: =원천데이터!G2668 -> 0.46921758 | O9: =원천데이터!G2934 -> 0.46512783 | P9: =원천데이터!G3200 -> 0.46747497 | Q9: =원천데이터!G3466 -> 0.46629723 | R9: =IFERROR(AVERAGE(D9:Q9),"") -> 0.46730325 | S9: =COUNT(D9:Q9) -> 14
A10: 서울 | B10: 강서구 | C10: 서울 강서구 | D10: =원천데이터!G10 -> 0.45292377 | E10: =원천데이터!G273 -> 0.45041158 | F10: =원천데이터!G536 -> 0.45216706 | G10: =원천데이터!G803 -> 0.458877 | H10: =원천데이터!G1071 -> 0.45626092 | I10: =원천데이터!G1339 -> 0.45846917 | J10: =원천데이터!G1605 -> 0.45837843 | K10: =원천데이터!G1871 -> 0.45646157 | L10: =원천데이터!G2137 -> 0.45078353 | M10: =원천데이터!G2403 -> 0.44032382 | N10: =원천데이터!G2669 -> 0.43898375 | O10: =원천데이터!G2935 -> 0.43657425 | P10: =원천데이터!G3201 -> 0.4346898 | Q10: =원천데이터!G3467 -> 0.43054824 | R10: =IFERROR(AVERAGE(D10:Q10),"") -> 0.44827521 | S10: =COUNT(D10:Q10) -> 14
A11: 서울 | B11: 관악구 | C11: 서울 관악구 | D11: =원천데이터!G11 -> 0.48237001 | E11: =원천데이터!G274 -> 0.47937041 | F11: =원천데이터!G537 -> 0.48084215 | G11: =원천데이터!G804 -> 0.48091548 | H11: =원천데이터!G1072 -> 0.48188941 | I11: =원천데이터!G1340 -> 0.48478305 | J11: =원천데이터!G1606 -> 0.4830129 | K11: =원천데이터!G1872 -> 0.4848736 | L11: =원천데이터!G2138 -> 0.48506994 | M11: =원천데이터!G2404 -> 0.4805701 | N11: =원천데이터!G2670 -> 0.47864694 | O11: =원천데이터!G2936 -> 0.47597105 | P11: =원천데이터!G3202 -> 0.47805162 | Q11: =원천데이터!G3468 -> 0.47719589 | R11: =IFERROR(AVERAGE(D11:Q11),"") -> 0.48096875 | S11: =COUNT(D11:Q11) -> 14
A12: 서울 | B12: 광진구 | C12: 서울 광진구 | D12: =원천데이터!G12 -> 0.44930177 | E12: =원천데이터!G275 -> 0.44735695 | F12: =원천데이터!G538 -> 0.44613656 | G12: =원천데이터!G805 -> 0.44596029 | H12: =원천데이터!G1073 -> 0.44828378 | I12: =원천데이터!G1341 -> 0.44868865 | J12: =원천데이터!G1607 -> 0.44845234 | K12: =원천데이터!G1873 -> 0.44812199 | L12: =원천데이터!G2139 -> 0.4489816 | M12: =원천데이터!G2405 -> 0.4459713 | N12: =원천데이터!G2671 -> 0.45011148 | O12: =원천데이터!G2937 -> 0.4482026 | P12: =원천데이터!G3203 -> 0.45000651 | Q12: =원천데이터!G3469 -> 0.44891339 | R12: =IFERROR(AVERAGE(D12:Q12),"") -> 0.4481778 | S12: =COUNT(D12:Q12) -> 14
A13: 서울 | B13: 구로구 | C13: 서울 구로구 | D13: =원천데이터!G13 -> 0.46666133 | E13: =원천데이터!G276 -> 0.46200009 | F13: =원천데이터!G539 -> 0.46010509 | G13: =원천데이터!G806 -> 0.46071377 | H13: =원천데이터!G1074 -> 0.45876562 | I13: =원천데이터!G1342 -> 0.45852435 | J13: =원천데이터!G1608 -> 0.45983423 | K13: =원천데이터!G1874 -> 0.46156583 | L13: =원천데이터!G2140 -> 0.4689319 | M13: =원천데이터!G2406 -> 0.46701743 | N13: =원천데이터!G2672 -> 0.46920374 | O13: =원천데이터!G2938 -> 0.4636086 | P13: =원천데이터!G3204 -> 0.46657302 | Q13: =원천데이터!G3470 -> 0.46598461 | R13: =IFERROR(AVERAGE(D13:Q13),"") -> 0.46353497 | S13: =COUNT(D13:Q13) -> 14
A14: 서울 | B14: 금천구 | C14: 서울 금천구 | D14: =원천데이터!G14 -> 0.47401121 | E14: =원천데이터!G277 -> 0.47204844 | F14: =원천데이터!G540 -> 0.47293792 | G14: =원천데이터!G807 -> 0.4753531 | H14: =원천데이터!G1075 -> 0.47652603 | I14: =원천데이터!G1343 -> 0.47856572 | J14: =원천데이터!G1609 -> 0.48013552 | K14: =원천데이터!G1875 -> 0.4800724 | L14: =원천데이터!G2141 -> 0.47943279 | M14: =원천데이터!G2407 -> 0.47859501 | N14: =원천데이터!G2673 -> 0.48165931 | O14: =원천데이터!G2939 -> 0.4757012 | P14: =원천데이터!G3205 -> 0.48067492 | Q14: =원천데이터!G3471 -> 0.48203163 | R14: =IFERROR(AVERAGE(D14:Q14),"") -> 0.47769609 | S14: =COUNT(D14:Q14) -> 14
A15: 서울 | B15: 노원구 | C15: 서울 노원구 | D15: =원천데이터!G15 -> 0.42077067 | E15: =원천데이터!G278 -> 0.41801575 | F15: =원천데이터!G541 -> 0.41430656 | G15: =원천데이터!G808 -> 0.41835037 | H15: =원천데이터!G1076 -> 0.41910992 | I15: =원천데이터!G1344 -> 0.42137611 | J15: =원천데이터!G1610 -> 0.4225285 | K15: =원천데이터!G1876 -> 0.42136029 | L15: =원천데이터!G2142 -> 0.42345227 | M15: =원천데이터!G2408 -> 0.41817367 | N15: =원천데이터!G2674 -> 0.42416631 | O15: =원천데이터!G2940 -> 0.42568189 | P15: =원천데이터!G3206 -> 0.42605765 | Q15: =원천데이터!G3472 -> 0.42773408 | R15: =IFERROR(AVERAGE(D15:Q15),"") -> 0.421506 | S15: =COUNT(D15:Q15) -> 14
A16: 서울 | B16: 도봉구 | C16: 서울 도봉구 | D16: =원천데이터!G16 -> 0.47107566 | E16: =원천데이터!G279 -> 0.46688332 | F16: =원천데이터!G542 -> 0.46806527 | G16: =원천데이터!G809 -> 0.46970471 | H16: =원천데이터!G1077 -> 0.47498916 | I16: =원천데이터!G1345 -> 0.47462217 | J16: =원천데이터!G1611 -> 0.47668012 | K16: =원천데이터!G1877 -> 0.47588776 | L16: =원천데이터!G2143 -> 0.4788029 | M16: =원천데이터!G2409 -> 0.47560811 | N16: =원천데이터!G2675 -> 0.48058959 | O16: =원천데이터!G2941 -> 0.47502342 | P16: =원천데이터!G3207 -> 0.47938565 | Q16: =원천데이터!G3473 -> 0.4789291 | R16: =IFERROR(AVERAGE(D16:Q16),"") -> 0.47473192 | S16: =COUNT(D16:Q16) -> 14
A17: 서울 | B17: 동대문구 | C17: 서울 동대문구 | D17: =원천데이터!G17 -> 0.44202496 | E17: =원천데이터!G280 -> 0.44080667 | F17: =원천데이터!G543 -> 0.44334858 | G17: =원천데이터!G810 -> 0.44518417 | H17: =원천데이터!G1078 -> 0.44563277 | I17: =원천데이터!G1346 -> 0.44706545 | J17: =원천데이터!G1612 -> 0.44893472 | K17: =원천데이터!G1878 -> 0.45227514 | L17: =원천데이터!G2144 -> 0.46185308 | M17: =원천데이터!G2410 -> 0.45757497 | N17: =원천데이터!G2676 -> 0.46010066 | O17: =원천데이터!G2942 -> 0.4590034 | P17: =원천데이터!G3208 -> 0.46666429 | Q17: =원천데이터!G3474 -> 0.46479669 | R17: =IFERROR(AVERAGE(D17:Q17),"") -> 0.45251897 | S17: =COUNT(D17:Q17) -> 14
... A49: 대구 | B49: 전체 | C49: 대구 | D49: =원천데이터!G49 -> 0.16524839 | E49: =원천데이터!G312 -> 0.16299644 | F49: =원천데이터!G575 -> 0.16263103 | G49: =원천데이터!G842 -> 0.16424244 | H49: =원천데이터!G1110 -> 0.16583886 | I49: =원천데이터!G1378 -> 0.16668544 | J49: =원천데이터!G1644 -> 0.16584858 | K49: =원천데이터!G1910 -> 0.16693081 | L49: =원천데이터!G2176 -> 0.16726686 | M49: =원천데이터!G2442 -> 0.15180972 | N49: =원천데이터!G2708 -> 0.1489993 | O49: =원천데이터!G2974 -> 0.16873644 | P49: =원천데이터!G3240 -> 0.17115852 | Q49: =원천데이터!G3506 -> 0.16933092 | R49: =IFERROR(AVERAGE(D49:Q49),"") -> 0.16412312 | S49: =COUNT(D49:Q49) -> 14
A50: 대구 | B50: 군위군 | C50: 대구 군위군 | P50: =원천데이터!G3241 -> 0.57176694 | Q50: =원천데이터!G3507 -> 0.5750449 | R50: =IFERROR(AVERAGE(D50:Q50),"") -> 0.57340592 | S50: =COUNT(D50:Q50) -> 2
A51: 대구 | B51: 남구 | C51: 대구 남구 | D51: =원천데이터!G50 -> 0.51469352 | E51: =원천데이터!G313 -> 0.51636228 | F51: =원천데이터!G576 -> 0.51210435 | G51: =원천데이터!G843 -> 0.51135196 | H51: =원천데이터!G1111 -> 0.51180759 | I51: =원천데이터!G1379 -> 0.51227263 | J51: =원천데이터!G1645 -> 0.51681561 | K51: =원천데이터!G1911 -> 0.5170465 | L51: =원천데이터!G2177 -> 0.52277574 | M51: =원천데이터!G2443 -> 0.52497305 | N51: =원천데이터!G2709 -> 0.52229821 | O51: =원천데이터!G2975 -> 0.51233426 | P51: =원천데이터!G3242 -> 0.51497756 | Q51: =원천데이터!G3508 -> 0.5189705 | R51: =IFERROR(AVERAGE(D51:Q51),"") -> 0.5163417 | S51: =COUNT(D51:Q51) -> 14
A52: 대구 | B52: 달서구 | C52: 대구 달서구 | D52: =원천데이터!G51 -> 0.41179294 | E52: =원천데이터!G314 -> 0.4130147 | F52: =원천데이터!G577 -> 0.42012025 | G52: =원천데이터!G844 -> 0.42307195 | H52: =원천데이터!G1112 -> 0.4260889 | I52: =원천데이터!G1380 -> 0.42921134 | J52: =원천데이터!G1646 -> 0.42916738 | K52: =원천데이터!G1912 -> 0.43115374 | L52: =원천데이터!G2178 -> 0.42858922 | M52: =원천데이터!G2444 -> 0.42069987 | N52: =원천데이터!G2710 -> 0.42541885 | O52: =원천데이터!G2976 -> 0.42907396 | P52: =원천데이터!G3243 -> 0.42585399 | Q52: =원천데이터!G3509 -> 0.42682308 | R52: =IFERROR(AVERAGE(D52:Q52),"") -> 0.42429144 | S52: =COUNT(D52:Q52) -> 14
A53: 대구 | B53: 달성군 | C53: 대구 달성군 | D53: =원천데이터!G52 -> 0.49254617 | E53: =원천데이터!G315 -> 0.48664546 | F53: =원천데이터!G578 -> 0.48464357 | G53: =원천데이터!G845 -> 0.48581085 | H53: =원천데이터!G1113 -> 0.49251193 | I53: =원천데이터!G1381 -> 0.49943012 | J53: =원천데이터!G1647 -> 0.4941268 | K53: =원천데이터!G1913 -> 0.48349256 | L53: =원천데이터!G2179 -> 0.48581302 | M53: =원천데이터!G2445 -> 0.48257312 | N53: =원천데이터!G2711 -> 0.482531 | O53: =원천데이터!G2977 -> 0.47678649 | P53: =원천데이터!G3244 -> 0.47340497 | Q53: =원천데이터!G3510 -> 0.46860963 | R53: =IFERROR(AVERAGE(D53:Q53),"") -> 0.48492326 | S53: =COUNT(D53:Q53) -> 14
A54: 대구 | B54: 동구 | C54: 대구 동구 | D54: =원천데이터!G53 -> 0.45243232 | E54: =원천데이터!G316 -> 0.45237979 | F54: =원천데이터!G579 -> 0.45666157 | G54: =원천데이터!G846 -> 0.45625174 | H54: =원천데이터!G1114 -> 0.45527352 | I54: =원천데이터!G1382 -> 0.45424444 | J54: =원천데이터!G1648 -> 0.45371721 | K54: =원천데이터!G1914 -> 0.45367758 | L54: =원천데이터!G2180 -> 0.45398114 | M54: =원천데이터!G2446 -> 0.45052868 | N54: =원천데이터!G2712 -> 0.45740987 | O54: =원천데이터!G2978 -> 0.45519462 | P54: =원천데이터!G3245 -> 0.45858944 | Q54: =원천데이터!G3511 -> 0.46101792 | R54: =IFERROR(AVERAGE(D54:Q54),"") -> 0.45509713 | S54: =COUNT(D54:Q54) -> 14
A55: 대구 | B55: 북구 | C55: 대구 북구 | D55: =원천데이터!G54 -> 0.40952254 | E55: =원천데이터!G317 -> 0.40778385 | F55: =원천데이터!G580 -> 0.40959033 | G55: =원천데이터!G847 -> 0.41160011 | H55: =원천데이터!G1115 -> 0.41524704 | I55: =원천데이터!G1383 -> 0.41976009 | J55: =원천데이터!G1649 -> 0.4239248 | K55: =원천데이터!G1915 -> 0.42585167 | L55: =원천데이터!G2181 -> 0.42933414 | M55: =원천데이터!G2447 -> 0.42999814 | N55: =원천데이터!G2713 -> 0.43316038 | O55: =원천데이터!G2979 -> 0.43369953 | P55: =원천데이터!G3246 -> 0.43318355 | Q55: =원천데이터!G3512 -> 0.43499816 | R55: =IFERROR(AVERAGE(D55:Q55),"") -> 0.4226896 | S55: =COUNT(D55:Q55) -> 14
A56: 대구 | B56: 서구 | C56: 대구 서구 | D56: =원천데이터!G55 -> 0.49609884 | E56: =원천데이터!G318 -> 0.4959112 | F56: =원천데이터!G581 -> 0.49546213 | G56: =원천데이터!G848 -> 0.49711378 | H56: =원천데이터!G1116 -> 0.50193516 | I56: =원천데이터!G1384 -> 0.50122111 | J56: =원천데이터!G1650 -> 0.50464286 | K56: =원천데이터!G1916 -> 0.50500452 | L56: =원천데이터!G2182 -> 0.50825552 | M56: =원천데이터!G2448 -> 0.51208811 | N56: =원천데이터!G2714 -> 0.51175423 | O56: =원천데이터!G2980 -> 0.50337706 | P56: =원천데이터!G3247 -> 0.51489268 | Q56: =원천데이터!G3513 -> 0.51181585 | R56: =IFERROR(AVERAGE(D56:Q56),"") -> 0.50425522 | S56: =COUNT(D56:Q56) -> 14
A57: 대구 | B57: 수성구 | C57: 대구 수성구 | D57: =원천데이터!G56 -> 0.44186326 | E57: =원천데이터!G319 -> 0.44000641 | F57: =원천데이터!G582 -> 0.44157795 | G57: =원천데이터!G849 -> 0.44214975 | H57: =원천데이터!G1117 -> 0.44366046 | I57: =원천데이터!G1385 -> 0.44619066 | J57: =원천데이터!G1651 -> 0.44498362 | K57: =원천데이터!G1917 -> 0.44946677 | L57: =원천데이터!G2183 -> 0.45257312 | M57: =원천데이터!G2449 -> 0.44957695 | N57: =원천데이터!G2715 -> 0.45284539 | O57: =원천데이터!G2981 -> 0.45434035 | P57: =원천데이터!G3248 -> 0.45456841 | Q57: =원천데이터!G3514 -> 0.45354091 | R57: =IFERROR(AVERAGE(D57:Q57),"") -> 0.44766743 | S57: =COUNT(D57:Q57) -> 14
A58: 대구 | B58: 중구 | C58: 대구 중구 | D58: =원천데이터!G57 -> 0.50564316 | E58: =원천데이터!G320 -> 0.50249123 | F58: =원천데이터!G583 -> 0.50383988 | G58: =원천데이터!G850 -> 0.5070449 | H58: =원천데이터!G1118 -> 0.51046369 | I58: =원천데이터!G1386 -> 0.51085931 | J58: =원천데이터!G1652 -> 0.50333722 | K58: =원천데이터!G1918 -> 0.50058998 | L58: =원천데이터!G2184 -> 0.5020772 | M58: =원천데이터!G2450 -> 0.50113043 | N58: =원천데이터!G2716 -> 0.50542515 | O58: =원천데이터!G2982 -> 0.50266562 | P58: =원천데이터!G3249 -> 0.50629883 | Q58: =원천데이터!G3515 -> 0.50502894 | R58: =IFERROR(AVERAGE(D58:Q58),"") -> 0.50477825 | S58: =COUNT(D58:Q58) -> 14
A59: 인천 | B59: 전체 | C59: 인천 | D59: =원천데이터!G58 -> 0.27709256 | E59: =원천데이터!G321 -> 0.27381841 | F59: =원천데이터!G584 -> 0.27725808 | G59: =원천데이터!G851 -> 0.27889404 | H59: =원천데이터!G1119 -> 0.27742824 | I59: =원천데이터!G1387 -> 0.28008279 | J59: =원천데이터!G1653 -> 0.28082562 | K59: =원천데이터!G1919 -> 0.27764405 | L59: =원천데이터!G2185 -> 0.27918229 | M59: =원천데이터!G2451 -> 0.26458103 | N59: =원천데이터!G2717 -> 0.26997967 | O59: =원천데이터!G2983 -> 0.28569433 | P59: =원천데이터!G3250 -> 0.28666501 | Q59: =원천데이터!G3516 -> 0.28393986 | R59: =IFERROR(AVERAGE(D59:Q59),"") -> 0.27807757 | S59: =COUNT(D59:Q59) -> 14
A60: 인천 | B60: 강화군 | C60: 인천 강화군 | D60: =원천데이터!G59 -> 0.45518327 | E60: =원천데이터!G322 -> 0.46135064 | F60: =원천데이터!G585 -> 0.46698778 | G60: =원천데이터!G852 -> 0.47278183 | H60: =원천데이터!G1120 -> 0.48082085 | I60: =원천데이터!G1388 -> 0.48782268 | J60: =원천데이터!G1654 -> 0.500922 | K60: =원천데이터!G1920 -> 0.49621574 | L60: =원천데이터!G2186 -> 0.49144915 | M60: =원천데이터!G2452 -> 0.48593164 | N60: =원천데이터!G2718 -> 0.48438981 | O60: =원천데이터!G2984 -> 0.48026885 | P60: =원천데이터!G3251 -> 0.48767869 | Q60: =원천데이터!G3517 -> 0.49399746 | R60: =IFERROR(AVERAGE(D60:Q60),"") -> 0.48184288 | S60: =COUNT(D60:Q60) -> 14
A61: 인천 | B61: 계양구 | C61: 인천 계양구 | D61: =원천데이터!G60 -> 0.42895877 | E61: =원천데이터!G323 -> 0.42148107 | F61: =원천데이터!G586 -> 0.42321653 | G61: =원천데이터!G853 -> 0.42490298 | H61: =원천데이터!G1121 -> 0.4235508 | I61: =원천데이터!G1389 -> 0.42687185 | J61: =원천데이터!G1655 -> 0.42493158 | K61: =원천데이터!G1921 -> 0.41934102 | L61: =원천데이터!G2187 -> 0.4208023 | M61: =원천데이터!G2453 -> 0.40923515 | N61: =원천데이터!G2719 -> 0.41669187 | O61: =원천데이터!G2985 -> 0.42142482 | P61: =원천데이터!G3252 -> 0.4194385 | Q61: =원천데이터!G3518 -> 0.42371391 | R61: =IFERROR(AVERAGE(D61:Q61),"") -> 0.42175437 | S61: =COUNT(D61:Q61) -> 14
A62: 인천 | B62: 남구 | C62: 인천 남구 | D62: =원천데이터!G61 -> 0.46262651 | E62: =원천데이터!G324 -> 0.45901544 | F62: =원천데이터!G587 -> 0.46140097 | G62: =원천데이터!G854 -> 0.46171882 | H62: =원천데이터!G1122 -> 0.46309655 | I62: =원천데이터!G1390 -> 0.47055477 | J62: =원천데이터!G1656 -> 0.46861731 | R62: =IFERROR(AVERAGE(D62:Q62),"") -> 0.46386148 | S62: =COUNT(D62:Q62) -> 7
A63: 인천 | B63: 남동구 | C63: 인천 남동구 | D63: =원천데이터!G62 -> 0.41998803 | E63: =원천데이터!G325 -> 0.41660612 | F63: =원천데이터!G588 -> 0.41662655 | G63: =원천데이터!G855 -> 0.4189343 | H63: =원천데이터!G1123 -> 0.42192961 | I63: =원천데이터!G1391 -> 0.4182822 | J63: =원천데이터!G1657 -> 0.42009027 | K63: =원천데이터!G1922 -> 0.41782126 | L63: =원천데이터!G2188 -> 0.41866565 | M63: =원천데이터!G2454 -> 0.41072391 | N63: =원천데이터!G2720 -> 0.41407704 | O63: =원천데이터!G2986 -> 0.419853 | P63: =원천데이터!G3253 -> 0.41584219 | Q63: =원천데이터!G3519 -> 0.42032637 | R63: =IFERROR(AVERAGE(D63:Q63),"") -> 0.41784047 | S63: =COUNT(D63:Q63) -> 14
A64: 인천 | B64: 동구 | C64: 인천 동구 | D64: =원천데이터!G63 -> 0.50145796 | E64: =원천데이터!G326 -> 0.49510223 | F64: =원천데이터!G589 -> 0.4954634 | G64: =원천데이터!G856 -> 0.49394166 | H64: =원천데이터!G1124 -> 0.49879397 | I64: =원천데이터!G1392 -> 0.49950591 | J64: =원천데이터!G1658 -> 0.50052784 | K64: =원천데이터!G1923 -> 0.49866084 | L64: =원천데이터!G2189 -> 0.50058271 | M64: =원천데이터!G2455 -> 0.502901 | N64: =원천데이터!G2721 -> 0.5082844 | O64: =원천데이터!G2987 -> 0.49559924 | P64: =원천데이터!G3254 -> 0.50932861 | Q64: =원천데이터!G3520 -> 0.51045829 | R64: =IFERROR(AVERAGE(D64:Q64),"") -> 0.50075772 | S64: =COUNT(D64:Q64) -> 14
A65: 인천 | B65: 미추홀구 | C65: 인천 미추홀구 | K65: =원천데이터!G1924 -> 0.46936432 | L65: =원천데이터!G2190 -> 0.4650971 | M65: =원천데이터!G2456 -> 0.46283636 | N65: =원천데이터!G2722 -> 0.46949062 | O65: =원천데이터!G2988 -> 0.46396729 | P65: =원천데이터!G3255 -> 0.46414836 | Q65: =원천데이터!G3521 -> 0.46133191 | R65: =IFERROR(AVERAGE(D65:Q65),"") -> 0.46517657 | S65: =COUNT(D65:Q65) -> 7
A66: 인천 | B66: 부평구 | C66: 인천 부평구 | D66: =원천데이터!G64 -> 0.42018469 | E66: =원천데이터!G327 -> 0.41384832 | F66: =원천데이터!G590 -> 0.41700149 | G66: =원천데이터!G857 -> 0.41956722 | H66: =원천데이터!G1125 -> 0.42126776 | I66: =원천데이터!G1393 -> 0.423913 | J66: =원천데이터!G1659 -> 0.42777026 | K66: =원천데이터!G1925 -> 0.42417984 | L66: =원천데이터!G2191 -> 0.42652738 | M66: =원천데이터!G2457 -> 0.41968026 | N66: =원천데이터!G2723 -> 0.4266089 | O66: =원천데이터!G2989 -> 0.43114545 | P66: =원천데이터!G3256 -> 0.43409707 | Q66: =원천데이터!G3522 -> 0.43033934 | R66: =IFERROR(AVERAGE(D66:Q66),"") -> 0.42400936 | S66: =COUNT(D66:Q66) -> 14
A67: 인천 | B67: 서구 | C67: 인천 서구 | D67: =원천데이터!G65 -> 0.42535587 | E67: =원천데이터!G328 -> 0.43171925 | F67: =원천데이터!G591 -> 0.42789156 | G67: =원천데이터!G858 -> 0.4207779 | H67: =원천데이터!G1126 -> 0.41212548 | I67: =원천데이터!G1394 -> 0.40650733 | J67: =원천데이터!G1660 -> 0.40507816 | K67: =원천데이터!G1926 -> 0.40504299 | L67: =원천데이터!G2192 -> 0.40355578 | M67: =원천데이터!G2458 -> 0.39109648 | N67: =원천데이터!G2724 -> 0.40626205 | O67: =원천데이터!G2990 -> 0.41147471 | P67: =원천데이터!G3257 -> 0.41523652 | Q67: =원천데이터!G3523 -> 0.40693364 | R67: =IFERROR(AVERAGE(D67:Q67),"") -> 0.41207555 | S67: =COUNT(D67:Q67) -> 14
A68: 인천 | B68: 연수구 | C68: 인천 연수구 | D68: =원천데이터!G66 -> 0.44714141 | E68: =원천데이터!G329 -> 0.43262224 | F68: =원천데이터!G592 -> 0.43356675 | G68: =원천데이터!G859 -> 0.4348879 | H68: =원천데이터!G1127 -> 0.43759816 | I68: =원천데이터!G1395 -> 0.43607199 | J68: =원천데이터!G1661 -> 0.43369536 | K68: =원천데이터!G1927 -> 0.43555413 | L68: =원천데이터!G2193 -> 0.43737916 | M68: =원천데이터!G2459 -> 0.43588828 | N68: =원천데이터!G2725 -> 0.42801164 | O68: =원천데이터!G2991 -> 0.42441263 | P68: =원천데이터!G3258 -> 0.42740557 | Q68: =원천데이터!G3524 -> 0.42426416 | R68: =IFERROR(AVERAGE(D68:Q68),"") -> 0.43346424 | S68: =COUNT(D68:Q68) -> 14
A69: 인천 | B69: 옹진군 | C69: 인천 옹진군 | D69: =원천데이터!G67 -> 0.60149635 | E69: =원천데이터!G330 -> 0.60194486 | F69: =원천데이터!G593 -> 0.5959746 | G69: =원천데이터!G860 -> 0.5906226 | H69: =원천데이터!G1128 -> 0.58905601 | I69: =원천데이터!G1396 -> 0.59644588 | J69: =원천데이터!G1662 -> 0.59962994 | K69: =원천데이터!G1928 -> 0.59953869 | L69: =원천데이터!G2194 -> 0.59922833 | M69: =원천데이터!G2460 -> 0.59837112 | N69: =원천데이터!G2726 -> 0.60270013 | O69: =원천데이터!G2992 -> 0.6001674 | P69: =원천데이터!G3259 -> 0.60194995 | Q69: =원천데이터!G3525 -> 0.60460646 | R69: =IFERROR(AVERAGE(D69:Q69),"") -> 0.59869517 | S69: =COUNT(D69:Q69) -> 14
A70: 인천 | B70: 중구 | C70: 인천 중구 | D70: =원천데이터!G68 -> 0.508522 | E70: =원천데이터!G331 -> 0.5100453 | F70: =원천데이터!G594 -> 0.5034784 | G70: =원천데이터!G861 -> 0.5028471 | H70: =원천데이터!G1129 -> 0.49379581 | I70: =원천데이터!G1397 -> 0.49224345 | J70: =원천데이터!G1663 -> 0.49093697 | K70: =원천데이터!G1929 -> 0.49543133 | L70: =원천데이터!G2195 -> 0.49244248 | M70: =원천데이터!G2461 -> 0.48491495 | N70: =원천데이터!G2727 -> 0.48579458 | O70: =원천데이터!G2993 -> 0.47686566 | P70: =원천데이터!G3260 -> 0.4687818 | Q70: =원천데이터!G3526 -> 0.46660683 | R70: =IFERROR(AVERAGE(D70:Q70),"") -> 0.49090762 | S70: =COUNT(D70:Q70) -> 14
A71: 광주 | B71: 전체 | C71: 광주 | D71: =원천데이터!G69 -> 0.19447265 | E71: =원천데이터!G332 -> 0.19269178 | F71: =원천데이터!G595 -> 0.1908819 | G71: =원천데이터!G862 -> 0.19169649 | H71: =원천데이터!G1130 -> 0.19525713 | I71: =원천데이터!G1398 -> 0.19335519 | J71: =원천데이터!G1664 -> 0.19396602 | K71: =원천데이터!G1930 -> 0.19117724 | L71: =원천데이터!G2196 -> 0.19261348 | M71: =원천데이터!G2462 -> 0.17942476 | N71: =원천데이터!G2728 -> 0.17840692 | O71: =원천데이터!G2994 -> 0.19685287 | P71: =원천데이터!G3261 -> 0.19848958 | Q71: =원천데이터!G3527 -> 0.19523027 | R71: =IFERROR(AVERAGE(D71:Q71),"") -> 0.19175116 | S71: =COUNT(D71:Q71) -> 14
A72: 광주 | B72: 광산구 | C72: 광주 광산구 | D72: =원천데이터!G70 -> 0.39652688 | E72: =원천데이터!G333 -> 0.38971253 | F72: =원천데이터!G596 -> 0.38981028 | G72: =원천데이터!G863 -> 0.39313836 | H72: =원천데이터!G1131 -> 0.39347699 | I72: =원천데이터!G1399 -> 0.39529649 | J72: =원천데이터!G1665 -> 0.39569472 | K72: =원천데이터!G1931 -> 0.39415037 | L72: =원천데이터!G2197 -> 0.39475848 | M72: =원천데이터!G2463 -> 0.39185183 | N72: =원천데이터!G2729 -> 0.39031201 | O72: =원천데이터!G2995 -> 0.39401821 | P72: =원천데이터!G3262 -> 0.39847911 | Q72: =원천데이터!G3528 -> 0.39638526 | R72: =IFERROR(AVERAGE(D72:Q72),"") -> 0.39382939 | S72: =COUNT(D72:Q72) -> 14
A73: 광주 | B73: 남구 | C73: 광주 남구 | D73: =원천데이터!G71 -> 0.47764669 | E73: =원천데이터!G334 -> 0.47574217 | F73: =원천데이터!G597 -> 0.47460993 | G73: =원천데이터!G864 -> 0.47501373 | H73: =원천데이터!G1132 -> 0.48015646 | I73: =원천데이터!G1400 -> 0.47743434 | J73: =원천데이터!G1666 -> 0.47312982 | K73: =원천데이터!G1932 -> 0.47085221 | L73: =원천데이터!G2198 -> 0.47310343 | M73: =원천데이터!G2464 -> 0.46787068 | N73: =원천데이터!G2730 -> 0.46871353 | O73: =원천데이터!G2996 -> 0.46651087 | P73: =원천데이터!G3263 -> 0.47067771 | Q73: =원천데이터!G3529 -> 0.46823346 | R73: =IFERROR(AVERAGE(D73:Q73),"") -> 0.47283536 | S73: =COUNT(D73:Q73) -> 14
...

Sheet 시도 요약
A1: 시도별 관외 유출률 요약
A3: 연도별 유출률과 2011~2024 평균. 행정구역 신설·통폐합으로 없는 연도는 빈칸이며 평균은 값이 존재하는 연도만 사용.
A5: 시도 | B5: 시군구 | C5: 지역명 | D5: 2011 | E5: 2012 | F5: 2013 | G5: 2014 | H5: 2015 | I5: 2016 | J5: 2017 | K5: 2018 | L5: 2019 | M5: 2020 | N5: 2021 | O5: 2022 | P5: 2023 | Q5: 2024 | R5: 2011~2024 평균 | S5: 관측연도 수
A6: 서울 | B6: 전체 | C6: 서울 | D6: =원천데이터!G6 -> 0.19331733 | E6: =원천데이터!G269 -> 0.19325337 | F6: =원천데이터!G532 -> 0.19393007 | G6: =원천데이터!G799 -> 0.19680529 | H6: =원천데이터!G1067 -> 0.1964465 | I6: =원천데이터!G1335 -> 0.1984181 | J6: =원천데이터!G1601 -> 0.19922236 | K6: =원천데이터!G1867 -> 0.19950336 | L6: =원천데이터!G2133 -> 0.20066118 | M6: =원천데이터!G2399 -> 0.19028605 | N6: =원천데이터!G2665 -> 0.19502784 | O6: =원천데이터!G2931 -> 0.21425469 | P6: =원천데이터!G3197 -> 0.21190936 | Q6: =원천데이터!G3463 -> 0.21071362 | R6: =IFERROR(AVERAGE(D6:Q6),"") -> 0.19955351 | S6: =COUNT(D6:Q6) -> 14
A7: 부산 | B7: 전체 | C7: 부산 | D7: =원천데이터!G32 -> 0.16627548 | E7: =원천데이터!G295 -> 0.16776914 | F7: =원천데이터!G558 -> 0.16864627 | G7: =원천데이터!G825 -> 0.17091559 | H7: =원천데이터!G1093 -> 0.17051812 | I7: =원천데이터!G1361 -> 0.17360283 | J7: =원천데이터!G1627 -> 0.17425843 | K7: =원천데이터!G1893 -> 0.17346041 | L7: =원천데이터!G2159 -> 0.17283885 | M7: =원천데이터!G2425 -> 0.15876958 | N7: =원천데이터!G2691 -> 0.16238657 | O7: =원천데이터!G2957 -> 0.17867871 | P7: =원천데이터!G3223 -> 0.17842422 | Q7: =원천데이터!G3489 -> 0.17342271 | R7: =IFERROR(AVERAGE(D7:Q7),"") -> 0.17071192 | S7: =COUNT(D7:Q7) -> 14
A8: 대구 | B8: 전체 | C8: 대구 | D8: =원천데이터!G49 -> 0.16524839 | E8: =원천데이터!G312 -> 0.16299644 | F8: =원천데이터!G575 -> 0.16263103 | G8: =원천데이터!G842 -> 0.16424244 | H8: =원천데이터!G1110 -> 0.16583886 | I8: =원천데이터!G1378 -> 0.16668544 | J8: =원천데이터!G1644 -> 0.16584858 | K8: =원천데이터!G1910 -> 0.16693081 | L8: =원천데이터!G2176 -> 0.16726686 | M8: =원천데이터!G2442 -> 0.15180972 | N8: =원천데이터!G2708 -> 0.1489993 | O8: =원천데이터!G2974 -> 0.16873644 | P8: =원천데이터!G3240 -> 0.17115852 | Q8: =원천데이터!G3506 -> 0.16933092 | R8: =IFERROR(AVERAGE(D8:Q8),"") -> 0.16412312 | S8: =COUNT(D8:Q8) -> 14
A9: 인천 | B9: 전체 | C9: 인천 | D9: =원천데이터!G58 -> 0.27709256 | E9: =원천데이터!G321 -> 0.27381841 | F9: =원천데이터!G584 -> 0.27725808 | G9: =원천데이터!G851 -> 0.27889404 | H9: =원천데이터!G1119 -> 0.27742824 | I9: =원천데이터!G1387 -> 0.28008279 | J9: =원천데이터!G1653 -> 0.28082562 | K9: =원천데이터!G1919 -> 0.27764405 | L9: =원천데이터!G2185 -> 0.27918229 | M9: =원천데이터!G2451 -> 0.26458103 | N9: =원천데이터!G2717 -> 0.26997967 | O9: =원천데이터!G2983 -> 0.28569433 | P9: =원천데이터!G3250 -> 0.28666501 | Q9: =원천데이터!G3516 -> 0.28393986 | R9: =IFERROR(AVERAGE(D9:Q9),"") -> 0.27807757 | S9: =COUNT(D9:Q9) -> 14
A10: 광주 | B10: 전체 | C10: 광주 | D10: =원천데이터!G69 -> 0.19447265 | E10: =원천데이터!G332 -> 0.19269178 | F10: =원천데이터!G595 -> 0.1908819 | G10: =원천데이터!G862 -> 0.19169649 | H10: =원천데이터!G1130 -> 0.19525713 | I10: =원천데이터!G1398 -> 0.19335519 | J10: =원천데이터!G1664 -> 0.19396602 | K10: =원천데이터!G1930 -> 0.19117724 | L10: =원천데이터!G2196 -> 0.19261348 | M10: =원천데이터!G2462 -> 0.17942476 | N10: =원천데이터!G2728 -> 0.17840692 | O10: =원천데이터!G2994 -> 0.19685287 | P10: =원천데이터!G3261 -> 0.19848958 | Q10: =원천데이터!G3527 -> 0.19523027 | R10: =IFERROR(AVERAGE(D10:Q10),"") -> 0.19175116 | S10: =COUNT(D10:Q10) -> 14
A11: 대전 | B11: 전체 | C11: 대전 | D11: =원천데이터!G75 -> 0.18957219 | E11: =원천데이터!G338 -> 0.18969845 | F11: =원천데이터!G601 -> 0.19022972 | G11: =원천데이터!G868 -> 0.19184461 | H11: =원천데이터!G1136 -> 0.19424726 | I11: =원천데이터!G1404 -> 0.19782711 | J11: =원천데이터!G1670 -> 0.20471157 | K11: =원천데이터!G1936 -> 0.20208869 | L11: =원천데이터!G2202 -> 0.20023929 | M11: =원천데이터!G2468 -> 0.18598465 | N11: =원천데이터!G2734 -> 0.18726673 | O11: =원천데이터!G3000 -> 0.20691363 | P11: =원천데이터!G3267 -> 0.20970254 | Q11: =원천데이터!G3533 -> 0.2091791 | R11: =IFERROR(AVERAGE(D11:Q11),"") -> 0.19710754 | S11: =COUNT(D11:Q11) -> 14
A12: 울산 | B12: 전체 | C12: 울산 | D12: =원천데이터!G81 -> 0.19038178 | E12: =원천데이터!G344 -> 0.19320428 | F12: =원천데이터!G607 -> 0.19368782 | G12: =원천데이터!G874 -> 0.19579612 | H12: =원천데이터!G1142 -> 0.2003099 | I12: =원천데이터!G1410 -> 0.201044 | J12: =원천데이터!G1676 -> 0.20219917 | K12: =원천데이터!G1942 -> 0.20107745 | L12: =원천데이터!G2208 -> 0.20276801 | M12: =원천데이터!G2474 -> 0.18006387 | N12: =원천데이터!G2740 -> 0.18291009 | O12: =원천데이터!G3006 -> 0.19999939 | P12: =원천데이터!G3273 -> 0.20326226 | Q12: =원천데이터!G3539 -> 0.19993816 | R12: =IFERROR(AVERAGE(D12:Q12),"") -> 0.19618874 | S12: =COUNT(D12:Q12) -> 14
A13: 세종 | B13: 전체 | C13: 세종 | E13: =원천데이터!G350 -> 0.50606176 | F13: =원천데이터!G613 -> 0.49747828 | G13: =원천데이터!G880 -> 0.52039158 | H13: =원천데이터!G1148 -> 0.50150675 | I13: =원천데이터!G1416 -> 0.47964156 | J13: =원천데이터!G1682 -> 0.46292927 | K13: =원천데이터!G1948 -> 0.45271063 | L13: =원천데이터!G2214 -> 0.44405596 | M13: =원천데이터!G2480 -> 0.42032459 | N13: =원천데이터!G2746 -> 0.40258852 | O13: =원천데이터!G3012 -> 0.39781144 | P13: =원천데이터!G3279 -> 0.39231409 | Q13: =원천데이터!G3545 -> 0.38600909 | R13: =IFERROR(AVERAGE(D13:Q13),"") -> 0.45106335 | S13: =COUNT(D13:Q13) -> 13
A14: 경기 | B14: 전체 | C14: 경기 | D14: =원천데이터!G87 -> 0.27093806 | E14: =원천데이터!G351 -> 0.27205805 | F14: =원천데이터!G614 -> 0.27283754 | G14: =원천데이터!G881 -> 0.27404922 | H14: =원천데이터!G1149 -> 0.27524958 | I14: =원천데이터!G1417 -> 0.2794813 | J14: =원천데이터!G1683 -> 0.27944173 | K14: =원천데이터!G1949 -> 0.28076258 | L14: =원천데이터!G2215 -> 0.28233497 | M14: =원천데이터!G2481 -> 0.26951293 | N14: =원천데이터!G2747 -> 0.27189519 | O14: =원천데이터!G3013 -> 0.28234645 | P14: =원천데이터!G3280 -> 0.28235482 | Q14: =원천데이터!G3546 -> 0.2789538 | R14: =IFERROR(AVERAGE(D14:Q14),"") -> 0.27658687 | S14: =COUNT(D14:Q14) -> 14
A15: 강원 | B15: 전체 | C15: 강원 | D15: =원천데이터!G129 -> 0.22380657 | E15: =원천데이터!G393 -> 0.22809789 | F15: =원천데이터!G659 -> 0.2320192 | G15: =원천데이터!G926 -> 0.23653463 | H15: =원천데이터!G1194 -> 0.23866921 | I15: =원천데이터!G1460 -> 0.24291335 | J15: =원천데이터!G1726 -> 0.24558332 | K15: =원천데이터!G1992 -> 0.24641632 | L15: =원천데이터!G2258 -> 0.24990405 | M15: =원천데이터!G2524 -> 0.23148609 | N15: =원천데이터!G2790 -> 0.23610763 | O15: =원천데이터!G3056 -> 0.24896966 | P15: =원천데이터!G3323 -> 0.25466926 | Q15: =원천데이터!G3591 -> 0.2551805 | R15: =IFERROR(AVERAGE(D15:Q15),"") -> 0.24073984 | S15: =COUNT(D15:Q15) -> 14
A16: 충북 | B16: 전체 | C16: 충북 | D16: =원천데이터!G148 -> 0.24273013 | E16: =원천데이터!G412 -> 0.24211255 | F16: =원천데이터!G678 -> 0.24356839 | G16: =원천데이터!G945 -> 0.24695927 | H16: =원천데이터!G1213 -> 0.24797445 | I16: =원천데이터!G1479 -> 0.25308215 | J16: =원천데이터!G1745 -> 0.25544938 | K16: =원천데이터!G2011 -> 0.25739323 | L16: =원천데이터!G2277 -> 0.25912369 | M16: =원천데이터!G2543 -> 0.24262539 | N16: =원천데이터!G2809 -> 0.24653572 | O16: =원천데이터!G3075 -> 0.2583815 | P16: =원천데이터!G3342 -> 0.26303998 | Q16: =원천데이터!G3610 -> 0.26311168 | R16: =IFERROR(AVERAGE(D16:Q16),"") -> 0.25157768 | S16: =COUNT(D16:Q16) -> 14
A17: 충남 | B17: 전체 | C17: 충남 | D17: =원천데이터!G162 -> 0.30652068 | E17: =원천데이터!G426 -> 0.28813337 | F17: =원천데이터!G692 -> 0.28966221 | G17: =원천데이터!G960 -> 0.29337565 | H17: =원천데이터!G1228 -> 0.29447063 | I17: =원천데이터!G1494 -> 0.30057356 | J17: =원천데이터!G1760 -> 0.30043607 | K17: =원천데이터!G2026 -> 0.30095423 | L17: =원천데이터!G2292 -> 0.30093729 | M17: =원천데이터!G2558 -> 0.28442337 | N17: =원천데이터!G2824 -> 0.29006906 | O17: =원천데이터!G3090 -> 0.30056752 | P17: =원천데이터!G3357 -> 0.30258243 | Q17: =원천데이터!G3625 -> 0.30033094 | R17: =IFERROR(AVERAGE(D17:Q17),"") -> 0.2966455 | S17: =COUNT(D17:Q17) -> 14
A18: 전북 | B18: 전체 | C18: 전북 | D18: =원천데이터!G179 -> 0.17997295 | E18: =원천데이터!G442 -> 0.18286157 | F18: =원천데이터!G709 -> 0.18487976 | G18: =원천데이터!G977 -> 0.18808318 | H18: =원천데이터!G1245 -> 0.18919158 | I18: =원천데이터!G1511 -> 0.19342169 | J18: =원천데이터!G1777 -> 0.1951863 | K18: =원천데이터!G2043 -> 0.19605227 | L18: =원천데이터!G2309 -> 0.19719987 | M18: =원천데이터!G2575 -> 0.17792125 | N18: =원천데이터!G2841 -> 0.17972977 | O18: =원천데이터!G3107 -> 0.19398874 | P18: =원천데이터!G3374 -> 0.19799841 | Q18: =원천데이터!G3642 -> 0.19645144 | R18: =IFERROR(AVERAGE(D18:Q18),"") -> 0.18949563 | S18: =COUNT(D18:Q18) -> 14
A19: 전남 | B19: 전체 | C19: 전남 | D19: =원천데이터!G195 -> 0.29547312 | E19: =원천데이터!G458 -> 0.29791225 | F19: =원천데이터!G725 -> 0.303954 | G19: =원천데이터!G993 -> 0.30757612 | H19: =원천데이터!G1261 -> 0.3114894 | I19: =원천데이터!G1527 -> 0.31576796 | J19: =원천데이터!G1793 -> 0.3181955 | K19: =원천데이터!G2059 -> 0.31970252 | L19: =원천데이터!G2325 -> 0.32163034 | M19: =원천데이터!G2591 -> 0.29897231 | N19: =원천데이터!G2857 -> 0.30112417 | O19: =원천데이터!G3123 -> 0.31059926 | P19: =원천데이터!G3390 -> 0.31581961 | Q19: =원천데이터!G3658 -> 0.31397428 | R19: =IFERROR(AVERAGE(D19:Q19),"") -> 0.3094422 | S19: =COUNT(D19:Q19) -> 14
A20: 경북 | B20: 전체 | C20: 경북 | D20: =원천데이터!G218 -> 0.28336056 | E20: =원천데이터!G481 -> 0.2836633 | F20: =원천데이터!G748 -> 0.28837891 | G20: =원천데이터!G1016 -> 0.29284096 | H20: =원천데이터!G1284 -> 0.2953744 | I20: =원천데이터!G1550 -> 0.30017844 | J20: =원천데이터!G1816 -> 0.30425652 | K20: =원천데이터!G2082 -> 0.30735735 | L20: =원천데이터!G2348 -> 0.31185137 | M20: =원천데이터!G2614 -> 0.29696004 | N20: =원천데이터!G2880 -> 0.30287528 | O20: =원천데이터!G3146 -> 0.31140151 | P20: =원천데이터!G3413 -> 0.31667448 | Q20: =원천데이터!G3681 -> 0.31551782 | R20: =IFERROR(AVERAGE(D20:Q20),"") -> 0.30076364 | S20: =COUNT(D20:Q20) -> 14
A21: 경남 | B21: 전체 | C21: 경남 | D21: =원천데이터!G243 -> 0.22138642 | E21: =원천데이터!G506 -> 0.22530718 | F21: =원천데이터!G773 -> 0.22826763 | G21: =원천데이터!G1041 -> 0.23241879 | H21: =원천데이터!G1309 -> 0.23423999 | I21: =원천데이터!G1575 -> 0.23666434 | J21: =원천데이터!G1841 -> 0.23952304 | K21: =원천데이터!G2107 -> 0.24194548 | L21: =원천데이터!G2373 -> 0.24233653 | M21: =원천데이터!G2639 -> 0.22398543 | N21: =원천데이터!G2905 -> 0.22776289 | O21: =원천데이터!G3171 -> 0.23835775 | P21: =원천데이터!G3437 -> 0.24241892 | Q21: =원천데이터!G3705 -> 0.24258162 | R21: =IFERROR(AVERAGE(D21:Q21),"") -> 0.23408543 | S21: =COUNT(D21:Q21) -> 14
A22: 제주 | B22: 전체 | C22: 제주 | D22: =원천데이터!G266 -> 0.13533499 | E22: =원천데이터!G529 -> 0.14168076 | F22: =원천데이터!G796 -> 0.14466963 | G22: =원천데이터!G1064 -> 0.15144644 | H22: =원천데이터!G1332 -> 0.15912965 | I22: =원천데이터!G1598 -> 0.17153866 | J22: =원천데이터!G1864 -> 0.17863234 | K22: =원천데이터!G2130 -> 0.18163366 | L22: =원천데이터!G2396 -> 0.18291447 | M22: =원천데이터!G2662 -> 0.15757908 | N22: =원천데이터!G2928 -> 0.16153176 | O22: =원천데이터!G3194 -> 0.18095043 | P22: =원천데이터!G3460 -> 0.18591007 | Q22: =원천데이터!G3728 -> 0.18400271 | R22: =IFERROR(AVERAGE(D22:Q22),"") -> 0.16549676 | S22: =COUNT(D22:Q22) -> 14

Sheet 원천데이터
A1: 지역별 의료이용 관외 유출률 - 원천데이터
A3: 유출률 = 관외 진료실인원수 / (관내 진료실인원수 + 관외 진료실인원수). 국민건강보험공단 연도별 통계연보의 관내-계·관외-계 시트만 사용.
A5: 연도 | B5: 시도 | C5: 시군구 | D5: 지역명 | E5: 관내 진료실인원수 | F5: 관외 진료실인원수 | G5: 유출률 | H5: 원천파일 | I5: 관내 시트 | J5: 관외 시트 | K5: 출처 URL
A6: 2011 | B6: 서울 | C6: 전체 | D6: 서울 | E6: 8963298 | F6: 2148008 | G6: =IFERROR(F6/(E6+F6),"") -> 0.19331733 | H6: region_04.xls | I6: 110p | J6: 122p | K6: https://www.nhis.or.kr/nhis/together/wbhaec06900m01.do?mode=view&articleNo=106342
A7: 2011 | B7: 서울 | C7: 강남구 | D7: 서울 강남구 | E7: 430738 | F7: 353460 | G7: =IFERROR(F7/(E7+F7),"") -> 0.450728 | H7: region_04.xls | I7: 110p | J7: 122p | K7: https://www.nhis.or.kr/nhis/together/wbhaec06900m01.do?mode=view&articleNo=106342
A8: 2011 | B8: 서울 | C8: 강동구 | D8: 서울 강동구 | E8: 391809 | F8: 261766 | G8: =IFERROR(F8/(E8+F8),"") -> 0.4005141 | H8: region_04.xls | I8: 110p | J8: 122p | K8: https://www.nhis.or.kr/nhis/together/wbhaec06900m01.do?mode=view&articleNo=106342
A9: 2011 | B9: 서울 | C9: 강북구 | D9: 서울 강북구 | E9: 255381 | F9: 226329 | G9: =IFERROR(F9/(E9+F9),"") -> 0.46984493 | H9: region_04.xls | I9: 110p | J9: 122p | K9: https://www.nhis.or.kr/nhis/together/wbhaec06900m01.do?mode=view&articleNo=106342
A10: 2011 | B10: 서울 | C10: 강서구 | D10: 서울 강서구 | E10: 434814 | F10: 359982 | G10: =IFERROR(F10/(E10+F10),"") -> 0.45292377 | H10: region_04.xls | I10: 110p | J10: 122p | K10: https://www.nhis.or.kr/nhis/together/wbhaec06900m01.do?mode=view&articleNo=106342
A11: 2011 | B11: 서울 | C11: 관악구 | D11: 서울 관악구 | E11: 377917 | F11: 352174 | G11: =IFERROR(F11/(E11+F11),"") -> 0.48237001 | H11: region_04.xls | I11: 110p | J11: 122p | K11: https://www.nhis.or.kr/nhis/together/wbhaec06900m01.do?mode=view&articleNo=106342
A12: 2011 | B12: 서울 | C12: 광진구 | D12: 서울 광진구 | E12: 280779 | F12: 229081 | G12: =IFERROR(F12/(E12+F12),"") -> 0.44930177 | H12: region_04.xls | I12: 110p | J12: 122p | K12: https://www.nhis.or.kr/nhis/together/wbhaec06900m01.do?mode=view&articleNo=106342
A13: 2011 | B13: 서울 | C13: 구로구 | D13: 서울 구로구 | E13: 319552 | F13: 279602 | G13: =IFERROR(F13/(E13+F13),"") -> 0.46666133 | H13: region_04.xls | I13: 110p | J13: 122p | K13: https://www.nhis.or.kr/nhis/together/wbhaec06900m01.do?mode=view&articleNo=106342
A14: 2011 | B14: 서울 | C14: 금천구 | D14: 서울 금천구 | E14: 178377 | F14: 160750 | G14: =IFERROR(F14/(E14+F14),"") -> 0.47401121 | H14: region_04.xls | I14: 110p | J14: 122p | K14: https://www.nhis.or.kr/nhis/together/wbhaec06900m01.do?mode=view&articleNo=106342
A15: 2011 | B15: 서울 | C15: 노원구 | D15: 서울 노원구 | E15: 471411 | F15: 342448 | G15: =IFERROR(F15/(E15+F15),"") -> 0.42077067 | H15: region_04.xls | I15: 110p | J15: 122p | K15: https://www.nhis.or.kr/nhis/together/wbhaec06900m01.do?mode=view&articleNo=106342
A16: 2011 | B16: 서울 | C16: 도봉구 | D16: 서울 도봉구 | E16: 272496 | F16: 242693 | G16: =IFERROR(F16/(E16+F16),"") -> 0.47107566 | H16: region_04.xls | I16: 110p | J16: 122p | K16: https://www.nhis.or.kr/nhis/together/wbhaec06900m01.do?mode=view&articleNo=106342
A17: 2011 | B17: 서울 | C17: 동대문구 | D17: 서울 동대문구 | E17: 273410 | F17: 216594 | G17: =IFERROR(F17/(E17+F17),"") -> 0.44202496 | H17: region_04.xls | I17: 110p | J17: 122p | K17: https://www.nhis.or.kr/nhis/together/wbhaec06900m01.do?mode=view&articleNo=106342
... A3730: 2024 | B3730: 제주 | C3730: 제주시 | D3730: 제주 제주시 | E3730: 455724 | F3730: 114646 | G3730: =IFERROR(F3730/(E3730+F3730),"") -> 0.20100286 | H3730: region_04.xlsx | I3730: 404p | J3730: 410p | K3730: https://www.nhis.or.kr/nhis/together/wbhaec06900m01.do?mode=view&articleNo=11006399

Sheet 검증
A1: 추출·계산 검증
A3: 연도별 원천 행 수와 계산 완료 건수를 비교합니다. 상태가 모두 OK인지 확인하세요.
A5: 연도 | B5: 원천 행 수 | C5: 유출률 계산 수 | D5: 미계산 건수 | E5: 상태
A6: 2011 | B6: =COUNTIF(원천데이터!$A$6:$A$3730,A6) -> 263 | C6: =COUNTIFS(원천데이터!$A$6:$A$3730,A6,원천데이터!$G$6:$G$3730,">=0") -> 263 | D6: =B6-C6 -> 0 | E6: =IF(D6=0,"OK","확인") -> OK
A7: 2012 | B7: =COUNTIF(원천데이터!$A$6:$A$3730,A7) -> 263 | C7: =COUNTIFS(원천데이터!$A$6:$A$3730,A7,원천데이터!$G$6:$G$3730,">=0") -> 263 | D7: =B7-C7 -> 0 | E7: =IF(D7=0,"OK","확인") -> OK
A8: 2013 | B8: =COUNTIF(원천데이터!$A$6:$A$3730,A8) -> 267 | C8: =COUNTIFS(원천데이터!$A$6:$A$3730,A8,원천데이터!$G$6:$G$3730,">=0") -> 267 | D8: =B8-C8 -> 0 | E8: =IF(D8=0,"OK","확인") -> OK
A9: 2014 | B9: =COUNTIF(원천데이터!$A$6:$A$3730,A9) -> 268 | C9: =COUNTIFS(원천데이터!$A$6:$A$3730,A9,원천데이터!$G$6:$G$3730,">=0") -> 268 | D9: =B9-C9 -> 0 | E9: =IF(D9=0,"OK","확인") -> OK
A10: 2015 | B10: =COUNTIF(원천데이터!$A$6:$A$3730,A10) -> 268 | C10: =COUNTIFS(원천데이터!$A$6:$A$3730,A10,원천데이터!$G$6:$G$3730,">=0") -> 268 | D10: =B10-C10 -> 0 | E10: =IF(D10=0,"OK","확인") -> OK
A11: 2016 | B11: =COUNTIF(원천데이터!$A$6:$A$3730,A11) -> 266 | C11: =COUNTIFS(원천데이터!$A$6:$A$3730,A11,원천데이터!$G$6:$G$3730,">=0") -> 266 | D11: =B11-C11 -> 0 | E11: =IF(D11=0,"OK","확인") -> OK
A12: 2017 | B12: =COUNTIF(원천데이터!$A$6:$A$3730,A12) -> 266 | C12: =COUNTIFS(원천데이터!$A$6:$A$3730,A12,원천데이터!$G$6:$G$3730,">=0") -> 266 | D12: =B12-C12 -> 0 | E12: =IF(D12=0,"OK","확인") -> OK
A13: 2018 | B13: =COUNTIF(원천데이터!$A$6:$A$3730,A13) -> 266 | C13: =COUNTIFS(원천데이터!$A$6:$A$3730,A13,원천데이터!$G$6:$G$3730,">=0") -> 266 | D13: =B13-C13 -> 0 | E13: =IF(D13=0,"OK","확인") -> OK
A14: 2019 | B14: =COUNTIF(원천데이터!$A$6:$A$3730,A14) -> 266 | C14: =COUNTIFS(원천데이터!$A$6:$A$3730,A14,원천데이터!$G$6:$G$3730,">=0") -> 266 | D14: =B14-C14 -> 0 | E14: =IF(D14=0,"OK","확인") -> OK
A15: 2020 | B15: =COUNTIF(원천데이터!$A$6:$A$3730,A15) -> 266 | C15: =COUNTIFS(원천데이터!$A$6:$A$3730,A15,원천데이터!$G$6:$G$3730,">=0") -> 266 | D15: =B15-C15 -> 0 | E15: =IF(D15=0,"OK","확인") -> OK
A16: 2021 | B16: =COUNTIF(원천데이터!$A$6:$A$3730,A16) -> 266 | C16: =COUNTIFS(원천데이터!$A$6:$A$3730,A16,원천데이터!$G$6:$G$3730,">=0") -> 266 | D16: =B16-C16 -> 0 | E16: =IF(D16=0,"OK","확인") -> OK
A17: 2022 | B17: =COUNTIF(원천데이터!$A$6:$A$3730,A17) -> 266 | C17: =COUNTIFS(원천데이터!$A$6:$A$3730,A17,원천데이터!$G$6:$G$3730,">=0") -> 266 | D17: =B17-C17 -> 0 | E17: =IF(D17=0,"OK","확인") -> OK
... A19: 2024 | B19: =COUNTIF(원천데이터!$A$6:$A$3730,A19) -> 268 | C19: =COUNTIFS(원천데이터!$A$6:$A$3730,A19,원천데이터!$G$6:$G$3730,">=0") -> 268 | D19: =B19-C19 -> 0 | E19: =IF(D19=0,"OK","확인") -> OK

Sheet 메타데이터
A1: 메타데이터 및 산출 기준
A3: 재현성과 해석을 위한 기준·출처·주의사항
A5: 구분 | B5: 항목 | C5: 내용 | D5: 출처
A6: 산식 | B6: 관외 유출률 | C6: 관외 진료실인원수 / (관내 진료실인원수 + 관외 진료실인원수) | D6: 원천데이터!G열
A7: 범위 | B7: 대상 기간 | C7: 2011~2024년 (14개 연도) | D7: NHIS 지역별 의료이용 통계연보
A8: 범위 | B8: 사용 시트 | C8: 시·군·구별 진료현황(관내-계), 시·군·구별 진료현황(관외-계) 및 이어지는 <계속> 시트만 사용 | D8: 각 원천파일의 관내·관외 시트
A9: 평균 | B9: 지역별 평균 | C9: 해당 지역에 값이 존재하는 연도의 단순 산술평균. 관측연도 수는 별도 표시. | D9: 지역별 유출률!R:S열
A10: 지역 | B10: 시도명 정규화 | C10: 특별·광역·특별자치 명칭을 서울·부산·강원·전북 등 단축명으로 통일. 시군구 원문명은 유지. | D10: 작성 규칙
A11: 주의 | B11: 행정구역 변경 | C11: 신설·통폐합 지역은 과거와 현재를 강제 연결하지 않음. 존재하지 않는 연도는 빈칸. | D11: 작성 규칙
A12: 주의 | B12: 지표 해석 | C12: 동일인이 관내와 관외를 모두 이용하면 양쪽 진료실인원수에 포함될 수 있어 고유 환자의 확률이 아니라 의료이용 비중 대리변수로 해석. | D12: 통계 정의 유의
A13: 검증 | B13: 짝 불일치 | C13: 관내·관외 지역명 짝 불일치 0건, 계산 가능 3,725건 | D13: 검증 시트
A14: 출처 | B14: 게시판 | C14: 국민건강보험공단 지역별 의료이용 통계연보 | D14: https://www.nhis.or.kr/nhis/together/wbhaec06900m01.do?mode=list

Sheet 보험개발원 위험률
A1: 보험개발원 참조순보험요율 위험률 원자료
A3: 적용시점: 2024년 4월 1일 이후 | 보간·연령 확장 없이 웹페이지에 제시된 대표연령 값을 그대로 수록
A4: 주의: 원문 페이지는 위험률 단위를 별도로 명시하지 않아, 아래 값은 웹페이지에 표시된 소수 비율 그대로입니다. 사망률 표명도 원문 표기(제9회 경험생명표)를 유지했습니다.
A6: 위험률 구분 | B6: 원문 표명 | C6: 연령(세) | D6: 남자 | E6: 여자 | F6: 원자료 간격 | G6: 적용시점 | H6: 원문 기준·주석 | I6: 출처 URL
A7: 사망률 | B7: 생존·사망률(제9회 경험생명표) | C7: 0 | D7: 0.00156 | E7: 0.00145 | F7: 5세 | G7: 2024-04-01 이후 | H7: 페이지 원문 표기 | I7: https://www.kidi.or.kr/user/nd81768.do
A8: 사망률 | B8: 생존·사망률(제9회 경험생명표) | C8: 5 | D8: 4e-05 | E8: 4e-05 | F8: 5세 | G8: 2024-04-01 이후 | H8: 페이지 원문 표기 | I8: https://www.kidi.or.kr/user/nd81768.do
A9: 사망률 | B9: 생존·사망률(제9회 경험생명표) | C9: 10 | D9: 3e-05 | E9: 3e-05 | F9: 5세 | G9: 2024-04-01 이후 | H9: 페이지 원문 표기 | I9: https://www.kidi.or.kr/user/nd81768.do
A10: 사망률 | B10: 생존·사망률(제9회 경험생명표) | C10: 15 | D10: 0.00014 | E10: 0.0001 | F10: 5세 | G10: 2024-04-01 이후 | H10: 페이지 원문 표기 | I10: https://www.kidi.or.kr/user/nd81768.do
A11: 사망률 | B11: 생존·사망률(제9회 경험생명표) | C11: 20 | D11: 0.00028 | E11: 0.0002 | F11: 5세 | G11: 2024-04-01 이후 | H11: 페이지 원문 표기 | I11: https://www.kidi.or.kr/user/nd81768.do
A12: 사망률 | B12: 생존·사망률(제9회 경험생명표) | C12: 25 | D12: 0.00039 | E12: 0.00024 | F12: 5세 | G12: 2024-04-01 이후 | H12: 페이지 원문 표기 | I12: https://www.kidi.or.kr/user/nd81768.do
A13: 사망률 | B13: 생존·사망률(제9회 경험생명표) | C13: 30 | D13: 0.00045 | E13: 0.00026 | F13: 5세 | G13: 2024-04-01 이후 | H13: 페이지 원문 표기 | I13: https://www.kidi.or.kr/user/nd81768.do
A14: 사망률 | B14: 생존·사망률(제9회 경험생명표) | C14: 35 | D14: 0.00053 | E14: 0.00035 | F14: 5세 | G14: 2024-04-01 이후 | H14: 페이지 원문 표기 | I14: https://www.kidi.or.kr/user/nd81768.do
A15: 사망률 | B15: 생존·사망률(제9회 경험생명표) | C15: 40 | D15: 0.00065 | E15: 0.00043 | F15: 5세 | G15: 2024-04-01 이후 | H15: 페이지 원문 표기 | I15: https://www.kidi.or.kr/user/nd81768.do
A16: 사망률 | B16: 생존·사망률(제9회 경험생명표) | C16: 45 | D16: 0.00093 | E16: 0.00055 | F16: 5세 | G16: 2024-04-01 이후 | H16: 페이지 원문 표기 | I16: https://www.kidi.or.kr/user/nd81768.do
A17: 사망률 | B17: 생존·사망률(제9회 경험생명표) | C17: 50 | D17: 0.00141 | E17: 0.00077 | F17: 5세 | G17: 2024-04-01 이후 | H17: 페이지 원문 표기 | I17: https://www.kidi.or.kr/user/nd81768.do
A18: 사망률 | B18: 생존·사망률(제9회 경험생명표) | C18: 55 | D18: 0.00216 | E18: 0.00105 | F18: 5세 | G18: 2024-04-01 이후 | H18: 페이지 원문 표기 | I18: https://www.kidi.or.kr/user/nd81768.do
... A75: 급성심근경색 발생률 | B75: 급성심근경색 발생률 | C75: 80 | D75: 0.002446 | E75: 0.001226 | F75: 10세 | G75: 2024-04-01 이후 | H75: 페이지 원문 표기 | I75: https://www.kidi.or.kr/user/nd81768.do

Sheet 보험개발원 위험률(1세)
A1: 보험개발원 위험률 — 1세 단위 선형보간
A3: 대표연령 원자료 사이의 값은 연령에 비례해 선형보간했습니다. 대표연령 값은 원자료 시트를 직접 참조합니다.
A4: 보간식: 하한 위험률 + (상한 위험률 − 하한 위험률) × (대상연령 − 하한연령) ÷ (상한연령 − 하한연령) | 외삽 없음
A6: 위험률 구분 | B6: 원문 표명 | C6: 연령(세) | D6: 남자 | E6: 여자 | F6: 값 구분 | G6: 보간 기준 연령 | H6: 원자료 간격 | I6: 적용시점 | J6: 출처 URL
A7: 사망률 | B7: 생존·사망률(제9회 경험생명표) | C7: 0 | D7: ='보험개발원 위험률'!D7 -> 0.00156 | E7: ='보험개발원 위험률'!E7 -> 0.00145 | F7: 원자료 | G7: 0세 원자료 | H7: 5세 | I7: 2024-04-01 이후 | J7: https://www.kidi.or.kr/user/nd81768.do
A8: 사망률 | B8: 생존·사망률(제9회 경험생명표) | C8: 1 | D8: ='보험개발원 위험률'!D7+('보험개발원 위험률'!D8-'보험개발원 위험률'!D7)*(C8-'보험개발원 위험률'!C7)/('보험개발원 위험률'!C8-'보험개발원 위험률'!C7) -> 0.001256 | E8: ='보험개발원 위험률'!E7+('보험개발원 위험률'!E8-'보험개발원 위험률'!E7)*(C8-'보험개발원 위험률'!C7)/('보험개발원 위험률'!C8-'보험개발원 위험률'!C7) -> 0.001168 | F8: 선형보간 | G8: 0~5세 | H8: 5세 | I8: 2024-04-01 이후 | J8: https://www.kidi.or.kr/user/nd81768.do
A9: 사망률 | B9: 생존·사망률(제9회 경험생명표) | C9: 2 | D9: ='보험개발원 위험률'!D7+('보험개발원 위험률'!D8-'보험개발원 위험률'!D7)*(C9-'보험개발원 위험률'!C7)/('보험개발원 위험률'!C8-'보험개발원 위험률'!C7) -> 0.000952 | E9: ='보험개발원 위험률'!E7+('보험개발원 위험률'!E8-'보험개발원 위험률'!E7)*(C9-'보험개발원 위험률'!C7)/('보험개발원 위험률'!C8-'보험개발원 위험률'!C7) -> 0.000886 | F9: 선형보간 | G9: 0~5세 | H9: 5세 | I9: 2024-04-01 이후 | J9: https://www.kidi.or.kr/user/nd81768.do
A10: 사망률 | B10: 생존·사망률(제9회 경험생명표) | C10: 3 | D10: ='보험개발원 위험률'!D7+('보험개발원 위험률'!D8-'보험개발원 위험률'!D7)*(C10-'보험개발원 위험률'!C7)/('보험개발원 위험률'!C8-'보험개발원 위험률'!C7) -> 0.000648 | E10: ='보험개발원 위험률'!E7+('보험개발원 위험률'!E8-'보험개발원 위험률'!E7)*(C10-'보험개발원 위험률'!C7)/('보험개발원 위험률'!C8-'보험개발원 위험률'!C7) -> 0.000604 | F10: 선형보간 | G10: 0~5세 | H10: 5세 | I10: 2024-04-01 이후 | J10: https://www.kidi.or.kr/user/nd81768.do
A11: 사망률 | B11: 생존·사망률(제9회 경험생명표) | C11: 4 | D11: ='보험개발원 위험률'!D7+('보험개발원 위험률'!D8-'보험개발원 위험률'!D7)*(C11-'보험개발원 위험률'!C7)/('보험개발원 위험률'!C8-'보험개발원 위험률'!C7) -> 0.000344 | E11: ='보험개발원 위험률'!E7+('보험개발원 위험률'!E8-'보험개발원 위험률'!E7)*(C11-'보험개발원 위험률'!C7)/('보험개발원 위험률'!C8-'보험개발원 위험률'!C7) -> 0.000322 | F11: 선형보간 | G11: 0~5세 | H11: 5세 | I11: 2024-04-01 이후 | J11: https://www.kidi.or.kr/user/nd81768.do
A12: 사망률 | B12: 생존·사망률(제9회 경험생명표) | C12: 5 | D12: ='보험개발원 위험률'!D8 -> 4e-05 | E12: ='보험개발원 위험률'!E8 -> 4e-05 | F12: 원자료 | G12: 5세 원자료 | H12: 5세 | I12: 2024-04-01 이후 | J12: https://www.kidi.or.kr/user/nd81768.do
A13: 사망률 | B13: 생존·사망률(제9회 경험생명표) | C13: 6 | D13: ='보험개발원 위험률'!D8+('보험개발원 위험률'!D9-'보험개발원 위험률'!D8)*(C13-'보험개발원 위험률'!C8)/('보험개발원 위험률'!C9-'보험개발원 위험률'!C8) -> 3.8e-05 | E13: ='보험개발원 위험률'!E8+('보험개발원 위험률'!E9-'보험개발원 위험률'!E8)*(C13-'보험개발원 위험률'!C8)/('보험개발원 위험률'!C9-'보험개발원 위험률'!C8) -> 3.8e-05 | F13: 선형보간 | G13: 5~10세 | H13: 5세 | I13: 2024-04-01 이후 | J13: https://www.kidi.or.kr/user/nd81768.do
A14: 사망률 | B14: 생존·사망률(제9회 경험생명표) | C14: 7 | D14: ='보험개발원 위험률'!D8+('보험개발원 위험률'!D9-'보험개발원 위험률'!D8)*(C14-'보험개발원 위험률'!C8)/('보험개발원 위험률'!C9-'보험개발원 위험률'!C8) -> 3.6e-05 | E14: ='보험개발원 위험률'!E8+('보험개발원 위험률'!E9-'보험개발원 위험률'!E8)*(C14-'보험개발원 위험률'!C8)/('보험개발원 위험률'!C9-'보험개발원 위험률'!C8) -> 3.6e-05 | F14: 선형보간 | G14: 5~10세 | H14: 5세 | I14: 2024-04-01 이후 | J14: https://www.kidi.or.kr/user/nd81768.do
A15: 사망률 | B15: 생존·사망률(제9회 경험생명표) | C15: 8 | D15: ='보험개발원 위험률'!D8+('보험개발원 위험률'!D9-'보험개발원 위험률'!D8)*(C15-'보험개발원 위험률'!C8)/('보험개발원 위험률'!C9-'보험개발원 위험률'!C8) -> 3.4e-05 | E15: ='보험개발원 위험률'!E8+('보험개발원 위험률'!E9-'보험개발원 위험률'!E8)*(C15-'보험개발원 위험률'!C8)/('보험개발원 위험률'!C9-'보험개발원 위험률'!C8) -> 3.4e-05 | F15: 선형보간 | G15: 5~10세 | H15: 5세 | I15: 2024-04-01 이후 | J15: https://www.kidi.or.kr/user/nd81768.do
A16: 사망률 | B16: 생존·사망률(제9회 경험생명표) | C16: 9 | D16: ='보험개발원 위험률'!D8+('보험개발원 위험률'!D9-'보험개발원 위험률'!D8)*(C16-'보험개발원 위험률'!C8)/('보험개발원 위험률'!C9-'보험개발원 위험률'!C8) -> 3.2e-05 | E16: ='보험개발원 위험률'!E8+('보험개발원 위험률'!E9-'보험개발원 위험률'!E8)*(C16-'보험개발원 위험률'!C8)/('보험개발원 위험률'!C9-'보험개발원 위험률'!C8) -> 3.2e-05 | F16: 선형보간 | G16: 5~10세 | H16: 5세 | I16: 2024-04-01 이후 | J16: https://www.kidi.or.kr/user/nd81768.do
A17: 사망률 | B17: 생존·사망률(제9회 경험생명표) | C17: 10 | D17: ='보험개발원 위험률'!D9 -> 3e-05 | E17: ='보험개발원 위험률'!E9 -> 3e-05 | F17: 원자료 | G17: 10세 원자료 | H17: 5세 | I17: 2024-04-01 이후 | J17: https://www.kidi.or.kr/user/nd81768.do
A18: 사망률 | B18: 생존·사망률(제9회 경험생명표) | C18: 11 | D18: ='보험개발원 위험률'!D9+('보험개발원 위험률'!D10-'보험개발원 위험률'!D9)*(C18-'보험개발원 위험률'!C9)/('보험개발원 위험률'!C10-'보험개발원 위험률'!C9) -> 5.2e-05 | E18: ='보험개발원 위험률'!E9+('보험개발원 위험률'!E10-'보험개발원 위험률'!E9)*(C18-'보험개발원 위험률'!C9)/('보험개발원 위험률'!C10-'보험개발원 위험률'!C9) -> 4.4e-05 | F18: 선형보간 | G18: 10~15세 | H18: 5세 | I18: 2024-04-01 이후 | J18: https://www.kidi.or.kr/user/nd81768.do
A19: 사망률 | B19: 생존·사망률(제9회 경험생명표) | C19: 12 | D19: ='보험개발원 위험률'!D9+('보험개발원 위험률'!D10-'보험개발원 위험률'!D9)*(C19-'보험개발원 위험률'!C9)/('보험개발원 위험률'!C10-'보험개발원 위험률'!C9) -> 7.4e-05 | E19: ='보험개발원 위험률'!E9+('보험개발원 위험률'!E10-'보험개발원 위험률'!E9)*(C19-'보험개발원 위험률'!C9)/('보험개발원 위험률'!C10-'보험개발원 위험률'!C9) -> 5.8e-05 | F19: 선형보간 | G19: 10~15세 | H19: 5세 | I19: 2024-04-01 이후 | J19: https://www.kidi.or.kr/user/nd81768.do
A20: 사망률 | B20: 생존·사망률(제9회 경험생명표) | C20: 13 | D20: ='보험개발원 위험률'!D9+('보험개발원 위험률'!D10-'보험개발원 위험률'!D9)*(C20-'보험개발원 위험률'!C9)/('보험개발원 위험률'!C10-'보험개발원 위험률'!C9) -> 9.6e-05 | E20: ='보험개발원 위험률'!E9+('보험개발원 위험률'!E10-'보험개발원 위험률'!E9)*(C20-'보험개발원 위험률'!C9)/('보험개발원 위험률'!C10-'보험개발원 위험률'!C9) -> 7.2e-05 | F20: 선형보간 | G20: 10~15세 | H20: 5세 | I20: 2024-04-01 이후 | J20: https://www.kidi.or.kr/user/nd81768.do
A21: 사망률 | B21: 생존·사망률(제9회 경험생명표) | C21: 14 | D21: ='보험개발원 위험률'!D9+('보험개발원 위험률'!D10-'보험개발원 위험률'!D9)*(C21-'보험개발원 위험률'!C9)/('보험개발원 위험률'!C10-'보험개발원 위험률'!C9) -> 0.000118 | E21: ='보험개발원 위험률'!E9+('보험개발원 위험률'!E10-'보험개발원 위험률'!E9)*(C21-'보험개발원 위험률'!C9)/('보험개발원 위험률'!C10-'보험개발원 위험률'!C9) -> 8.6e-05 | F21: 선형보간 | G21: 10~15세 | H21: 5세 | I21: 2024-04-01 이후 | J21: https://www.kidi.or.kr/user/nd81768.do
A22: 사망률 | B22: 생존·사망률(제9회 경험생명표) | C22: 15 | D22: ='보험개발원 위험률'!D10 -> 0.00014 | E22: ='보험개발원 위험률'!E10 -> 0.0001 | F22: 원자료 | G22: 15세 원자료 | H22: 5세 | I22: 2024-04-01 이후 | J22: https://www.kidi.or.kr/user/nd81768.do
A23: 사망률 | B23: 생존·사망률(제9회 경험생명표) | C23: 16 | D23: ='보험개발원 위험률'!D10+('보험개발원 위험률'!D11-'보험개발원 위험률'!D10)*(C23-'보험개발원 위험률'!C10)/('보험개발원 위험률'!C11-'보험개발원 위험률'!C10) -> 0.000168 | E23: ='보험개발원 위험률'!E10+('보험개발원 위험률'!E11-'보험개발원 위험률'!E10)*(C23-'보험개발원 위험률'!C10)/('보험개발원 위험률'!C11-'보험개발원 위험률'!C10) -> 0.00012 | F23: 선형보간 | G23: 15~20세 | H23: 5세 | I23: 2024-04-01 이후 | J23: https://www.kidi.or.kr/user/nd81768.do
A24: 사망률 | B24: 생존·사망률(제9회 경험생명표) | C24: 17 | D24: ='보험개발원 위험률'!D10+('보험개발원 위험률'!D11-'보험개발원 위험률'!D10)*(C24-'보험개발원 위험률'!C10)/('보험개발원 위험률'!C11-'보험개발원 위험률'!C10) -> 0.000196 | E24: ='보험개발원 위험률'!E10+('보험개발원 위험률'!E11-'보험개발원 위험률'!E10)*(C24-'보험개발원 위험률'!C10)/('보험개발원 위험률'!C11-'보험개발원 위험률'!C10) -> 0.00014 | F24: 선형보간 | G24: 15~20세 | H24: 5세 | I24: 2024-04-01 이후 | J24: https://www.kidi.or.kr/user/nd81768.do
A25: 사망률 | B25: 생존·사망률(제9회 경험생명표) | C25: 18 | D25: ='보험개발원 위험률'!D10+('보험개발원 위험률'!D11-'보험개발원 위험률'!D10)*(C25-'보험개발원 위험률'!C10)/('보험개발원 위험률'!C11-'보험개발원 위험률'!C10) -> 0.000224 | E25: ='보험개발원 위험률'!E10+('보험개발원 위험률'!E11-'보험개발원 위험률'!E10)*(C25-'보험개발원 위험률'!C10)/('보험개발원 위험률'!C11-'보험개발원 위험률'!C10) -> 0.00016 | F25: 선형보간 | G25: 15~20세 | H25: 5세 | I25: 2024-04-01 이후 | J25: https://www.kidi.or.kr/user/nd81768.do
A26: 사망률 | B26: 생존·사망률(제9회 경험생명표) | C26: 19 | D26: ='보험개발원 위험률'!D10+('보험개발원 위험률'!D11-'보험개발원 위험률'!D10)*(C26-'보험개발원 위험률'!C10)/('보험개발원 위험률'!C11-'보험개발원 위험률'!C10) -> 0.000252 | E26: ='보험개발원 위험률'!E10+('보험개발원 위험률'!E11-'보험개발원 위험률'!E10)*(C26-'보험개발원 위험률'!C10)/('보험개발원 위험률'!C11-'보험개발원 위험률'!C10) -> 0.00018 | F26: 선형보간 | G26: 15~20세 | H26: 5세 | I26: 2024-04-01 이후 | J26: https://www.kidi.or.kr/user/nd81768.do
A27: 사망률 | B27: 생존·사망률(제9회 경험생명표) | C27: 20 | D27: ='보험개발원 위험률'!D11 -> 0.00028 | E27: ='보험개발원 위험률'!E11 -> 0.0002 | F27: 원자료 | G27: 20세 원자료 | H27: 5세 | I27: 2024-04-01 이후 | J27: https://www.kidi.or.kr/user/nd81768.do
A28: 사망률 | B28: 생존·사망률(제9회 경험생명표) | C28: 21 | D28: ='보험개발원 위험률'!D11+('보험개발원 위험률'!D12-'보험개발원 위험률'!D11)*(C28-'보험개발원 위험률'!C11)/('보험개발원 위험률'!C12-'보험개발원 위험률'!C11) -> 0.000302 | E28: ='보험개발원 위험률'!E11+('보험개발원 위험률'!E12-'보험개발원 위험률'!E11)*(C28-'보험개발원 위험률'!C11)/('보험개발원 위험률'!C12-'보험개발원 위험률'!C11) -> 0.000208 | F28: 선형보간 | G28: 20~25세 | H28: 5세 | I28: 2024-04-01 이후 | J28: https://www.kidi.or.kr/user/nd81768.do
A29: 사망률 | B29: 생존·사망률(제9회 경험생명표) | C29: 22 | D29: ='보험개발원 위험률'!D11+('보험개발원 위험률'!D12-'보험개발원 위험률'!D11)*(C29-'보험개발원 위험률'!C11)/('보험개발원 위험률'!C12-'보험개발원 위험률'!C11) -> 0.000324 | E29: ='보험개발원 위험률'!E11+('보험개발원 위험률'!E12-'보험개발원 위험률'!E11)*(C29-'보험개발원 위험률'!C11)/('보험개발원 위험률'!C12-'보험개발원 위험률'!C11) -> 0.000216 | F29: 선형보간 | G29: 20~25세 | H29: 5세 | I29: 2024-04-01 이후 | J29: https://www.kidi.or.kr/user/nd81768.do
A30: 사망률 | B30: 생존·사망률(제9회 경험생명표) | C30: 23 | D30: ='보험개발원 위험률'!D11+('보험개발원 위험률'!D12-'보험개발원 위험률'!D11)*(C30-'보험개발원 위험률'!C11)/('보험개발원 위험률'!C12-'보험개발원 위험률'!C11) -> 0.000346 | E30: ='보험개발원 위험률'!E11+('보험개발원 위험률'!E12-'보험개발원 위험률'!E11)*(C30-'보험개발원 위험률'!C11)/('보험개발원 위험률'!C12-'보험개발원 위험률'!C11) -> 0.000224 | F30: 선형보간 | G30: 20~25세 | H30: 5세 | I30: 2024-04-01 이후 | J30: https://www.kidi.or.kr/user/nd81768.do
A31: 사망률 | B31: 생존·사망률(제9회 경험생명표) | C31: 24 | D31: ='보험개발원 위험률'!D11+('보험개발원 위험률'!D12-'보험개발원 위험률'!D11)*(C31-'보험개발원 위험률'!C11)/('보험개발원 위험률'!C12-'보험개발원 위험률'!C11) -> 0.000368 | E31: ='보험개발원 위험률'!E11+('보험개발원 위험률'!E12-'보험개발원 위험률'!E11)*(C31-'보험개발원 위험률'!C11)/('보험개발원 위험률'!C12-'보험개발원 위험률'!C11) -> 0.000232 | F31: 선형보간 | G31: 20~25세 | H31: 5세 | I31: 2024-04-01 이후 | J31: https://www.kidi.or.kr/user/nd81768.do
A32: 사망률 | B32: 생존·사망률(제9회 경험생명표) | C32: 25 | D32: ='보험개발원 위험률'!D12 -> 0.00039 | E32: ='보험개발원 위험률'!E12 -> 0.00024 | F32: 원자료 | G32: 25세 원자료 | H32: 5세 | I32: 2024-04-01 이후 | J32: https://www.kidi.or.kr/user/nd81768.do
A33: 사망률 | B33: 생존·사망률(제9회 경험생명표) | C33: 26 | D33: ='보험개발원 위험률'!D12+('보험개발원 위험률'!D13-'보험개발원 위험률'!D12)*(C33-'보험개발원 위험률'!C12)/('보험개발원 위험률'!C13-'보험개발원 위험률'!C12) -> 0.000402 | E33: ='보험개발원 위험률'!E12+('보험개발원 위험률'!E13-'보험개발원 위험률'!E12)*(C33-'보험개발원 위험률'!C12)/('보험개발원 위험률'!C13-'보험개발원 위험률'!C12) -> 0.000244 | F33: 선형보간 | G33: 25~30세 | H33: 5세 | I33: 2024-04-01 이후 | J33: https://www.kidi.or.kr/user/nd81768.do
A34: 사망률 | B34: 생존·사망률(제9회 경험생명표) | C34: 27 | D34: ='보험개발원 위험률'!D12+('보험개발원 위험률'!D13-'보험개발원 위험률'!D12)*(C34-'보험개발원 위험률'!C12)/('보험개발원 위험률'!C13-'보험개발원 위험률'!C12) -> 0.000414 | E34: ='보험개발원 위험률'!E12+('보험개발원 위험률'!E13-'보험개발원 위험률'!E12)*(C34-'보험개발원 위험률'!C12)/('보험개발원 위험률'!C13-'보험개발원 위험률'!C12) -> 0.000248 | F34: 선형보간 | G34: 25~30세 | H34: 5세 | I34: 2024-04-01 이후 | J34: https://www.kidi.or.kr/user/nd81768.do
A35: 사망률 | B35: 생존·사망률(제9회 경험생명표) | C35: 28 | D35: ='보험개발원 위험률'!D12+('보험개발원 위험률'!D13-'보험개발원 위험률'!D12)*(C35-'보험개발원 위험률'!C12)/('보험개발원 위험률'!C13-'보험개발원 위험률'!C12) -> 0.000426 | E35: ='보험개발원 위험률'!E12+('보험개발원 위험률'!E13-'보험개발원 위험률'!E12)*(C35-'보험개발원 위험률'!C12)/('보험개발원 위험률'!C13-'보험개발원 위험률'!C12) -> 0.000252 | F35: 선형보간 | G35: 25~30세 | H35: 5세 | I35: 2024-04-01 이후 | J35: https://www.kidi.or.kr/user/nd81768.do
A36: 사망률 | B36: 생존·사망률(제9회 경험생명표) | C36: 29 | D36: ='보험개발원 위험률'!D12+('보험개발원 위험률'!D13-'보험개발원 위험률'!D12)*(C36-'보험개발원 위험률'!C12)/('보험개발원 위험률'!C13-'보험개발원 위험률'!C12) -> 0.000438 | E36: ='보험개발원 위험률'!E12+('보험개발원 위험률'!E13-'보험개발원 위험률'!E12)*(C36-'보험개발원 위험률'!C12)/('보험개발원 위험률'!C13-'보험개발원 위험률'!C12) -> 0.000256 | F36: 선형보간 | G36: 25~30세 | H36: 5세 | I36: 2024-04-01 이후 | J36: https://www.kidi.or.kr/user/nd81768.do
A37: 사망률 | B37: 생존·사망률(제9회 경험생명표) | C37: 30 | D37: ='보험개발원 위험률'!D13 -> 0.00045 | E37: ='보험개발원 위험률'!E13 -> 0.00026 | F37: 원자료 | G37: 30세 원자료 | H37: 5세 | I37: 2024-04-01 이후 | J37: https://www.kidi.or.kr/user/nd81768.do
A38: 사망률 | B38: 생존·사망률(제9회 경험생명표) | C38: 31 | D38: ='보험개발원 위험률'!D13+('보험개발원 위험률'!D14-'보험개발원 위험률'!D13)*(C38-'보험개발원 위험률'!C13)/('보험개발원 위험률'!C14-'보험개발원 위험률'!C13) -> 0.000466 | E38: ='보험개발원 위험률'!E13+('보험개발원 위험률'!E14-'보험개발원 위험률'!E13)*(C38-'보험개발원 위험률'!C13)/('보험개발원 위험률'!C14-'보험개발원 위험률'!C13) -> 0.000278 | F38: 선형보간 | G38: 30~35세 | H38: 5세 | I38: 2024-04-01 이후 | J38: https://www.kidi.or.kr/user/nd81768.do
A39: 사망률 | B39: 생존·사망률(제9회 경험생명표) | C39: 32 | D39: ='보험개발원 위험률'!D13+('보험개발원 위험률'!D14-'보험개발원 위험률'!D13)*(C39-'보험개발원 위험률'!C13)/('보험개발원 위험률'!C14-'보험개발원 위험률'!C13) -> 0.000482 | E39: ='보험개발원 위험률'!E13+('보험개발원 위험률'!E14-'보험개발원 위험률'!E13)*(C39-'보험개발원 위험률'!C13)/('보험개발원 위험률'!C14-'보험개발원 위험률'!C13) -> 0.000296 | F39: 선형보간 | G39: 30~35세 | H39: 5세 | I39: 2024-04-01 이후 | J39: https://www.kidi.or.kr/user/nd81768.do
A40: 사망률 | B40: 생존·사망률(제9회 경험생명표) | C40: 33 | D40: ='보험개발원 위험률'!D13+('보험개발원 위험률'!D14-'보험개발원 위험률'!D13)*(C40-'보험개발원 위험률'!C13)/('보험개발원 위험률'!C14-'보험개발원 위험률'!C13) -> 0.000498 | E40: ='보험개발원 위험률'!E13+('보험개발원 위험률'!E14-'보험개발원 위험률'!E13)*(C40-'보험개발원 위험률'!C13)/('보험개발원 위험률'!C14-'보험개발원 위험률'!C13) -> 0.000314 | F40: 선형보간 | G40: 30~35세 | H40: 5세 | I40: 2024-04-01 이후 | J40: https://www.kidi.or.kr/user/nd81768.do
A41: 사망률 | B41: 생존·사망률(제9회 경험생명표) | C41: 34 | D41: ='보험개발원 위험률'!D13+('보험개발원 위험률'!D14-'보험개발원 위험률'!D13)*(C41-'보험개발원 위험률'!C13)/('보험개발원 위험률'!C14-'보험개발원 위험률'!C13) -> 0.000514 | E41: ='보험개발원 위험률'!E13+('보험개발원 위험률'!E14-'보험개발원 위험률'!E13)*(C41-'보험개발원 위험률'!C13)/('보험개발원 위험률'!C14-'보험개발원 위험률'!C13) -> 0.000332 | F41: 선형보간 | G41: 30~35세 | H41: 5세 | I41: 2024-04-01 이후 | J41: https://www.kidi.or.kr/user/nd81768.do
A42: 사망률 | B42: 생존·사망률(제9회 경험생명표) | C42: 35 | D42: ='보험개발원 위험률'!D14 -> 0.00053 | E42: ='보험개발원 위험률'!E14 -> 0.00035 | F42: 원자료 | G42: 35세 원자료 | H42: 5세 | I42: 2024-04-01 이후 | J42: https://www.kidi.or.kr/user/nd81768.do
...

Sheet 계리기호
A1: 질병별·성별 계리기호 (0~80세)
A3: 예정이율(연) | B3: 0.021 | D3: 할인계수 v | E3: =1/(1+$B$3) -> 0.97943193 | G3: 기준계약수 l₀ | H3: 100000 | J3: 계산연령 | K3: 0~80세 | M3: 진단보험금 지급 | N3: 기말 | P3: 보험료 납입 | Q3: 기초
A4: 계산가정: 사망과 해당 질병 진단을 경쟁탈퇴로 반영합니다. 유효 진단률=(1−사망률)×질병발생률, 유지율=(1−사망률)×(1−질병발생률). 진단보험금은 기말 지급이므로 Cₓ=v^(x+1)·dₓ이며, Nₓ와 Mₓ는 80세까지 후방누계합니다.
A5: 암 · 남자 | L5: 암 · 여자 | W5: 뇌졸중 · 남자 | AH5: 뇌졸중 · 여자 | AS5: 급성심근경색 · 남자 | BD5: 급성심근경색 · 여자
A6: 연령 x | B6: 사망률 qₓ | C6: 질병발생률 iₓ | D6: 유효 진단률 qₓᵈ | E6: lₓ | F6: dₓᵈ | G6: Dₓ | H6: Cₓᵈ | I6: Nₓ | J6: Mₓᵈ | L6: 연령 x | M6: 사망률 qₓ | N6: 질병발생률 iₓ | O6: 유효 진단률 qₓᵈ | P6: lₓ | Q6: dₓᵈ | R6: Dₓ | S6: Cₓᵈ | T6: Nₓ | U6: Mₓᵈ | W6: 연령 x | X6: 사망률 qₓ | Y6: 질병발생률 iₓ | Z6: 유효 진단률 qₓᵈ | AA6: lₓ | AB6: dₓᵈ | AC6: Dₓ | AD6: Cₓᵈ | AE6: Nₓ | AF6: Mₓᵈ | AH6: 연령 x | AI6: 사망률 qₓ | AJ6: 질병발생률 iₓ | AK6: 유효 진단률 qₓᵈ | AL6: lₓ | AM6: dₓᵈ | AN6: Dₓ | AO6: Cₓᵈ | AP6: Nₓ | AQ6: Mₓᵈ | AS6: 연령 x | AT6: 사망률 qₓ | AU6: 질병발생률 iₓ | AV6: 유효 진단률 qₓᵈ | AW6: lₓ | AX6: dₓᵈ | AY6: Dₓ | AZ6: Cₓᵈ | BA6: Nₓ | BB6: Mₓᵈ | BD6: 연령 x | BE6: 사망률 qₓ | BF6: 질병발생률 iₓ | BG6: 유효 진단률 qₓᵈ | BH6: lₓ | BI6: dₓᵈ | BJ6: Dₓ | BK6: Cₓᵈ | BL6: Nₓ | BM6: Mₓᵈ
A7: 0 | B7: ='보험개발원 위험률(1세)'!D7 -> 0.00156 | C7: ='보험개발원 위험률(1세)'!D209 -> 0.000419 | D7: =(1-B7)*C7 -> 0.00041834636 | E7: =$H$3 -> 100000 | F7: =E7*D7 -> 41.834636 | G7: =$E$3^A7*E7 -> 100000 | H7: =$E$3^(A7+1)*F7 -> 40.974178 | I7: =G7+I8 -> 3729195.7 | J7: =H7+J8 -> 9354.5522 | L7: 0 | M7: ='보험개발원 위험률(1세)'!E7 -> 0.00145 | N7: ='보험개발원 위험률(1세)'!E209 -> 0.00039 | O7: =(1-M7)*N7 -> 0.0003894345 | P7: =$H$3 -> 100000 | Q7: =P7*O7 -> 38.94345 | R7: =$E$3^L7*P7 -> 100000 | S7: =$E$3^(L7+1)*Q7 -> 38.142458 | T7: =R7+T8 -> 3720791.8 | U7: =S7+U8 -> 9045.9239 | W7: 0 | X7: ='보험개발원 위험률(1세)'!D7 -> 0.00156 | Y7: ='보험개발원 위험률(1세)'!D290 -> 0.000289 | Z7: =(1-X7)*Y7 -> 0.00028854916 | AA7: =$H$3 -> 100000 | AB7: =AA7*Z7 -> 28.854916 | AC7: =$E$3^W7*AA7 -> 100000 | AD7: =$E$3^(W7+1)*AB7 -> 28.261426 | AE7: =AC7+AE8 -> 3816634.6 | AF7: =AD7+AF8 -> 3636.2213 | AH7: 0 | AI7: ='보험개발원 위험률(1세)'!E7 -> 0.00145 | AJ7: ='보험개발원 위험률(1세)'!E290 -> 0.0002 | AK7: =(1-AI7)*AJ7 -> 0.00019971 | AL7: =$H$3 -> 100000 | AM7: =AL7*AK7 -> 19.971 | AN7: =$E$3^AH7*AL7 -> 100000 | AO7: =$E$3^(AH7+1)*AM7 -> 19.560235 | AP7: =AN7+AP8 -> 3868727.1 | AQ7: =AO7+AQ8 -> 2567.2469 | AS7: 0 | AT7: ='보험개발원 위험률(1세)'!D7 -> 0.00156 | AU7: ='보험개발원 위험률(1세)'!D371 -> 2e-06 | AV7: =(1-AT7)*AU7 -> 1.99688e-06 | AW7: =$H$3 -> 100000 | AX7: =AW7*AV7 -> 0.199688 | AY7: =$E$3^AS7*AW7 -> 100000 | AZ7: =$E$3^(AS7+1)*AX7 -> 0.1955808 | BA7: =AY7+BA8 -> 3848881.5 | BB7: =AZ7+BB8 -> 1415.097 | BD7: 0 | BE7: ='보험개발원 위험률(1세)'!E7 -> 0.00145 | BF7: ='보험개발원 위험률(1세)'!E371 -> 3e-06 | BG7: =(1-BE7)*BF7 -> 2.99565e-06 | BH7: =$H$3 -> 100000 | BI7: =BH7*BG7 -> 0.299565 | BJ7: =$E$3^BD7*BH7 -> 100000 | BK7: =$E$3^(BD7+1)*BI7 -> 0.29340353 | BL7: =BJ7+BL8 -> 3901144 | BM7: =BK7+BM8 -> 371.94971
A8: 1 | B8: ='보험개발원 위험률(1세)'!D8 -> 0.001256 | C8: ='보험개발원 위험률(1세)'!D210 -> 0.0003917 | D8: =(1-B8)*C8 -> 0.00039120802 | E8: =E7*(1-B7)*(1-C7) -> 99802.165 | F8: =E8*D8 -> 39.043408 | G8: =$E$3^A8*E8 -> 97749.427 | H8: =$E$3^(A8+1)*F8 -> 37.45383 | I8: =G8+I9 -> 3629195.7 | J8: =H8+J9 -> 9313.578 | L8: 1 | M8: ='보험개발원 위험률(1세)'!E8 -> 0.001168 | N8: ='보험개발원 위험률(1세)'!E210 -> 0.0003664 | O8: =(1-M8)*N8 -> 0.00036597204 | P8: =P7*(1-M7)*(1-N7) -> 99816.057 | Q8: =P8*O8 -> 36.529886 | R8: =$E$3^L8*P8 -> 97763.033 | S8: =$E$3^(L8+1)*Q8 -> 35.042642 | T8: =R8+T9 -> 3620791.8 | U8: =S8+U9 -> 9007.7815 | W8: 1 | X8: ='보험개발원 위험률(1세)'!D8 -> 0.001256 | Y8: ='보험개발원 위험률(1세)'!D291 -> 0.0002629 | Z8: =(1-X8)*Y8 -> 0.0002625698 | AA8: =AA7*(1-X7)*(1-Y7) -> 99815.145 | AB8: =AA8*Z8 -> 26.208442 | AC8: =$E$3^W8*AA8 -> 97762.14 | AD8: =$E$3^(W8+1)*AB8 -> 25.141416 | AE8: =AC8+AE9 -> 3716634.6 | AF8: =AD8+AF9 -> 3607.9599 | AH8: 1 | AI8: ='보험개발원 위험률(1세)'!E8 -> 0.001168 | AJ8: ='보험개발원 위험률(1세)'!E291 -> 0.0001824 | AK8: =(1-AI8)*AJ8 -> 0.00018218696 | AL8: =AL7*(1-AI7)*(1-AJ7) -> 99835.029 | AM8: =AL8*AK8 -> 18.18864 | AN8: =$E$3^AH8*AL8 -> 97781.615 | AO8: =$E$3^(AH8+1)*AM8 -> 17.448124 | AP8: =AN8+AP9 -> 3768727.1 | AQ8: =AO8+AQ9 -> 2547.6866 | AS8: 1 | AT8: ='보험개발원 위험률(1세)'!D8 -> 0.001256 | AU8: ='보험개발원 위험률(1세)'!D372 -> 2.1e-06 | AV8: =(1-AT8)*AU8 -> 2.0973624e-06 | AW8: =AW7*(1-AT7)*(1-AU7) -> 99843.8 | AX8: =AW8*AV8 -> 0.20940863 | AY8: =$E$3^AS8*AW8 -> 97790.206 | AZ8: =$E$3^(AS8+1)*AX8 -> 0.20088296 | BA8: =AY8+BA9 -> 3748881.5 | BB8: =AZ8+BB9 -> 1414.9014 | BD8: 1 | BE8: ='보험개발원 위험률(1세)'!E8 -> 0.001168 | BF8: ='보험개발원 위험률(1세)'!E372 -> 2.8e-06 | BG8: =(1-BE8)*BF8 -> 2.7967296e-06 | BH8: =BH7*(1-BE7)*(1-BF7) -> 99854.7 | BI8: =BH8*BG8 -> 0.2792666 | BJ8: =$E$3^BD8*BH8 -> 97800.882 | BK8: =$E$3^(BD8+1)*BI8 -> 0.26789679 | BL8: =BJ8+BL9 -> 3801144 | BM8: =BK8+BM9 -> 371.65631
